[2025-01-26 15:21:08,654: INFO: main: Welcome to our custom log]
[2025-01-26 15:24:00,322: INFO: main: Welcome to our custom log]
[2025-03-03 23:15:38,250: INFO: common: yaml file: config\config.yaml loaded successfully]
[2025-03-03 23:15:38,265: INFO: common: yaml file: params.yaml loaded successfully]
[2025-03-03 23:15:38,267: INFO: common: created directory at: artifacts]
[2025-03-03 23:15:38,271: INFO: common: created directory at: artifacts/data_ingestion]
[2025-03-03 23:15:38,272: INFO: 986331348: Downloading data from https://drive.google.com/file/d/1vlhZ5c7abUKF8xXERIw6m9Te8fW7ohw3/view?usp=sharing into file artifacts/data_ingestion/data.zip]
[2025-03-03 23:16:37,429: INFO: 986331348: Downloaded data from https://drive.google.com/file/d/1vlhZ5c7abUKF8xXERIw6m9Te8fW7ohw3/view?usp=sharing into file artifacts/data_ingestion/data.zip]
[2025-03-03 23:33:08,098: INFO: main: >>>>>> stage Data Ingestion stage started <<<<<<]
[2025-03-03 23:33:08,100: INFO: common: yaml file: config\config.yaml loaded successfully]
[2025-03-03 23:33:08,101: INFO: common: yaml file: params.yaml loaded successfully]
[2025-03-03 23:33:08,102: INFO: common: created directory at: artifacts]
[2025-03-03 23:33:08,103: INFO: common: created directory at: artifacts/data_ingestion]
[2025-03-03 23:33:08,103: INFO: data_ingestion: Downloading data from https://drive.google.com/file/d/1vlhZ5c7abUKF8xXERIw6m9Te8fW7ohw3/view?usp=sharing into file artifacts/data_ingestion/data.zip]
[2025-03-03 23:33:42,783: ERROR: main: ("Connection broken: ConnectionAbortedError(10053, 'An established connection was aborted by the software in your host machine', None, 10053, None)", ConnectionAbortedError(10053, 'An established connection was aborted by the software in your host machine', None, 10053, None))]
Traceback (most recent call last):
  File "C:\Users\PCAdmin\.conda\envs\kidney\lib\site-packages\urllib3\response.py", line 748, in _error_catcher
    yield
  File "C:\Users\PCAdmin\.conda\envs\kidney\lib\site-packages\urllib3\response.py", line 873, in _raw_read
    data = self._fp_read(amt, read1=read1) if not fp_closed else b""
  File "C:\Users\PCAdmin\.conda\envs\kidney\lib\site-packages\urllib3\response.py", line 856, in _fp_read
    return self._fp.read(amt) if amt is not None else self._fp.read()
  File "C:\Users\PCAdmin\.conda\envs\kidney\lib\http\client.py", line 459, in read
    n = self.readinto(b)
  File "C:\Users\PCAdmin\.conda\envs\kidney\lib\http\client.py", line 503, in readinto
    n = self.fp.readinto(b)
  File "C:\Users\PCAdmin\.conda\envs\kidney\lib\socket.py", line 681, in readinto
    return self._sock.recv_into(b)
  File "C:\Users\PCAdmin\.conda\envs\kidney\lib\ssl.py", line 1274, in recv_into
    return self.read(nbytes, buffer)
  File "C:\Users\PCAdmin\.conda\envs\kidney\lib\ssl.py", line 1132, in read
    return self._sslobj.read(len, buffer)
ConnectionAbortedError: [WinError 10053] An established connection was aborted by the software in your host machine

The above exception was the direct cause of the following exception:

Traceback (most recent call last):
  File "C:\Users\PCAdmin\.conda\envs\kidney\lib\site-packages\requests\models.py", line 820, in generate
    yield from self.raw.stream(chunk_size, decode_content=True)
  File "C:\Users\PCAdmin\.conda\envs\kidney\lib\site-packages\urllib3\response.py", line 1060, in stream
    data = self.read(amt=amt, decode_content=decode_content)
  File "C:\Users\PCAdmin\.conda\envs\kidney\lib\site-packages\urllib3\response.py", line 949, in read
    data = self._raw_read(amt)
  File "C:\Users\PCAdmin\.conda\envs\kidney\lib\site-packages\urllib3\response.py", line 902, in _raw_read
    self._fp.close()
  File "C:\Users\PCAdmin\.conda\envs\kidney\lib\contextlib.py", line 131, in __exit__
    self.gen.throw(type, value, traceback)
  File "C:\Users\PCAdmin\.conda\envs\kidney\lib\site-packages\urllib3\response.py", line 775, in _error_catcher
    raise ProtocolError(f"Connection broken: {e!r}", e) from e
urllib3.exceptions.ProtocolError: ("Connection broken: ConnectionAbortedError(10053, 'An established connection was aborted by the software in your host machine', None, 10053, None)", ConnectionAbortedError(10053, 'An established connection was aborted by the software in your host machine', None, 10053, None))

During handling of the above exception, another exception occurred:

Traceback (most recent call last):
  File "main.py", line 8, in <module>
    data_ingestion.main()
  File "c:\users\pcadmin\documents\keshtech\dsml\kidney-disease-classification-deep-learning-project\src\cnnClassifier\pipeline\stage_01_data_ingestion.py", line 15, in main
    data_ingestion.download_file()
  File "c:\users\pcadmin\documents\keshtech\dsml\kidney-disease-classification-deep-learning-project\src\cnnClassifier\components\data_ingestion.py", line 31, in download_file
    raise e
  File "c:\users\pcadmin\documents\keshtech\dsml\kidney-disease-classification-deep-learning-project\src\cnnClassifier\components\data_ingestion.py", line 26, in download_file
    gdown.download(prefix+file_id,zip_download_dir)
  File "C:\Users\PCAdmin\.conda\envs\kidney\lib\site-packages\gdown\download.py", line 368, in download
    for chunk in res.iter_content(chunk_size=CHUNK_SIZE):
  File "C:\Users\PCAdmin\.conda\envs\kidney\lib\site-packages\requests\models.py", line 822, in generate
    raise ChunkedEncodingError(e)
requests.exceptions.ChunkedEncodingError: ("Connection broken: ConnectionAbortedError(10053, 'An established connection was aborted by the software in your host machine', None, 10053, None)", ConnectionAbortedError(10053, 'An established connection was aborted by the software in your host machine', None, 10053, None))
[2025-03-03 23:34:26,791: INFO: main: >>>>>> stage Data Ingestion stage started <<<<<<]
[2025-03-03 23:34:26,792: INFO: common: yaml file: config\config.yaml loaded successfully]
[2025-03-03 23:34:26,793: INFO: common: yaml file: params.yaml loaded successfully]
[2025-03-03 23:34:26,793: INFO: common: created directory at: artifacts]
[2025-03-03 23:34:26,794: INFO: common: created directory at: artifacts/data_ingestion]
[2025-03-03 23:34:26,794: INFO: data_ingestion: Downloading data from https://drive.google.com/file/d/1vlhZ5c7abUKF8xXERIw6m9Te8fW7ohw3/view?usp=sharing into file artifacts/data_ingestion/data.zip]
[2025-03-03 23:34:53,246: ERROR: main: ("Connection broken: ConnectionAbortedError(10053, 'An established connection was aborted by the software in your host machine', None, 10053, None)", ConnectionAbortedError(10053, 'An established connection was aborted by the software in your host machine', None, 10053, None))]
Traceback (most recent call last):
  File "C:\Users\PCAdmin\.conda\envs\kidney\lib\site-packages\urllib3\response.py", line 748, in _error_catcher
    yield
  File "C:\Users\PCAdmin\.conda\envs\kidney\lib\site-packages\urllib3\response.py", line 873, in _raw_read
    data = self._fp_read(amt, read1=read1) if not fp_closed else b""
  File "C:\Users\PCAdmin\.conda\envs\kidney\lib\site-packages\urllib3\response.py", line 856, in _fp_read
    return self._fp.read(amt) if amt is not None else self._fp.read()
  File "C:\Users\PCAdmin\.conda\envs\kidney\lib\http\client.py", line 459, in read
    n = self.readinto(b)
  File "C:\Users\PCAdmin\.conda\envs\kidney\lib\http\client.py", line 503, in readinto
    n = self.fp.readinto(b)
  File "C:\Users\PCAdmin\.conda\envs\kidney\lib\socket.py", line 681, in readinto
    return self._sock.recv_into(b)
  File "C:\Users\PCAdmin\.conda\envs\kidney\lib\ssl.py", line 1274, in recv_into
    return self.read(nbytes, buffer)
  File "C:\Users\PCAdmin\.conda\envs\kidney\lib\ssl.py", line 1132, in read
    return self._sslobj.read(len, buffer)
ConnectionAbortedError: [WinError 10053] An established connection was aborted by the software in your host machine

The above exception was the direct cause of the following exception:

Traceback (most recent call last):
  File "C:\Users\PCAdmin\.conda\envs\kidney\lib\site-packages\requests\models.py", line 820, in generate
    yield from self.raw.stream(chunk_size, decode_content=True)
  File "C:\Users\PCAdmin\.conda\envs\kidney\lib\site-packages\urllib3\response.py", line 1060, in stream
    data = self.read(amt=amt, decode_content=decode_content)
  File "C:\Users\PCAdmin\.conda\envs\kidney\lib\site-packages\urllib3\response.py", line 949, in read
    data = self._raw_read(amt)
  File "C:\Users\PCAdmin\.conda\envs\kidney\lib\site-packages\urllib3\response.py", line 902, in _raw_read
    self._fp.close()
  File "C:\Users\PCAdmin\.conda\envs\kidney\lib\contextlib.py", line 131, in __exit__
    self.gen.throw(type, value, traceback)
  File "C:\Users\PCAdmin\.conda\envs\kidney\lib\site-packages\urllib3\response.py", line 775, in _error_catcher
    raise ProtocolError(f"Connection broken: {e!r}", e) from e
urllib3.exceptions.ProtocolError: ("Connection broken: ConnectionAbortedError(10053, 'An established connection was aborted by the software in your host machine', None, 10053, None)", ConnectionAbortedError(10053, 'An established connection was aborted by the software in your host machine', None, 10053, None))

During handling of the above exception, another exception occurred:

Traceback (most recent call last):
  File "main.py", line 8, in <module>
    data_ingestion.main()
  File "c:\users\pcadmin\documents\keshtech\dsml\kidney-disease-classification-deep-learning-project\src\cnnClassifier\pipeline\stage_01_data_ingestion.py", line 15, in main
    data_ingestion.download_file()
  File "c:\users\pcadmin\documents\keshtech\dsml\kidney-disease-classification-deep-learning-project\src\cnnClassifier\components\data_ingestion.py", line 31, in download_file
    raise e
  File "c:\users\pcadmin\documents\keshtech\dsml\kidney-disease-classification-deep-learning-project\src\cnnClassifier\components\data_ingestion.py", line 26, in download_file
    gdown.download(prefix+file_id,zip_download_dir)
  File "C:\Users\PCAdmin\.conda\envs\kidney\lib\site-packages\gdown\download.py", line 368, in download
    for chunk in res.iter_content(chunk_size=CHUNK_SIZE):
  File "C:\Users\PCAdmin\.conda\envs\kidney\lib\site-packages\requests\models.py", line 822, in generate
    raise ChunkedEncodingError(e)
requests.exceptions.ChunkedEncodingError: ("Connection broken: ConnectionAbortedError(10053, 'An established connection was aborted by the software in your host machine', None, 10053, None)", ConnectionAbortedError(10053, 'An established connection was aborted by the software in your host machine', None, 10053, None))
[2025-03-03 23:35:30,544: INFO: main: >>>>>> stage Data Ingestion stage started <<<<<<]
[2025-03-03 23:35:30,545: INFO: common: yaml file: config\config.yaml loaded successfully]
[2025-03-03 23:35:30,546: INFO: common: yaml file: params.yaml loaded successfully]
[2025-03-03 23:35:30,547: INFO: common: created directory at: artifacts]
[2025-03-03 23:35:30,547: INFO: common: created directory at: artifacts/data_ingestion]
[2025-03-03 23:35:30,549: INFO: data_ingestion: Downloading data from https://drive.google.com/file/d/1vlhZ5c7abUKF8xXERIw6m9Te8fW7ohw3/view?usp=sharing into file artifacts/data_ingestion/data.zip]
[2025-03-03 23:37:19,064: ERROR: main: ("Connection broken: ConnectionAbortedError(10053, 'An established connection was aborted by the software in your host machine', None, 10053, None)", ConnectionAbortedError(10053, 'An established connection was aborted by the software in your host machine', None, 10053, None))]
Traceback (most recent call last):
  File "C:\Users\PCAdmin\.conda\envs\kidney\lib\site-packages\urllib3\response.py", line 748, in _error_catcher
    yield
  File "C:\Users\PCAdmin\.conda\envs\kidney\lib\site-packages\urllib3\response.py", line 873, in _raw_read
    data = self._fp_read(amt, read1=read1) if not fp_closed else b""
  File "C:\Users\PCAdmin\.conda\envs\kidney\lib\site-packages\urllib3\response.py", line 856, in _fp_read
    return self._fp.read(amt) if amt is not None else self._fp.read()
  File "C:\Users\PCAdmin\.conda\envs\kidney\lib\http\client.py", line 459, in read
    n = self.readinto(b)
  File "C:\Users\PCAdmin\.conda\envs\kidney\lib\http\client.py", line 503, in readinto
    n = self.fp.readinto(b)
  File "C:\Users\PCAdmin\.conda\envs\kidney\lib\socket.py", line 681, in readinto
    return self._sock.recv_into(b)
  File "C:\Users\PCAdmin\.conda\envs\kidney\lib\ssl.py", line 1274, in recv_into
    return self.read(nbytes, buffer)
  File "C:\Users\PCAdmin\.conda\envs\kidney\lib\ssl.py", line 1132, in read
    return self._sslobj.read(len, buffer)
ConnectionAbortedError: [WinError 10053] An established connection was aborted by the software in your host machine

The above exception was the direct cause of the following exception:

Traceback (most recent call last):
  File "C:\Users\PCAdmin\.conda\envs\kidney\lib\site-packages\requests\models.py", line 820, in generate
    yield from self.raw.stream(chunk_size, decode_content=True)
  File "C:\Users\PCAdmin\.conda\envs\kidney\lib\site-packages\urllib3\response.py", line 1060, in stream
    data = self.read(amt=amt, decode_content=decode_content)
  File "C:\Users\PCAdmin\.conda\envs\kidney\lib\site-packages\urllib3\response.py", line 949, in read
    data = self._raw_read(amt)
  File "C:\Users\PCAdmin\.conda\envs\kidney\lib\site-packages\urllib3\response.py", line 902, in _raw_read
    self._fp.close()
  File "C:\Users\PCAdmin\.conda\envs\kidney\lib\contextlib.py", line 131, in __exit__
    self.gen.throw(type, value, traceback)
  File "C:\Users\PCAdmin\.conda\envs\kidney\lib\site-packages\urllib3\response.py", line 775, in _error_catcher
    raise ProtocolError(f"Connection broken: {e!r}", e) from e
urllib3.exceptions.ProtocolError: ("Connection broken: ConnectionAbortedError(10053, 'An established connection was aborted by the software in your host machine', None, 10053, None)", ConnectionAbortedError(10053, 'An established connection was aborted by the software in your host machine', None, 10053, None))

During handling of the above exception, another exception occurred:

Traceback (most recent call last):
  File "main.py", line 8, in <module>
    data_ingestion.main()
  File "c:\users\pcadmin\documents\keshtech\dsml\kidney-disease-classification-deep-learning-project\src\cnnClassifier\pipeline\stage_01_data_ingestion.py", line 15, in main
    data_ingestion.download_file()
  File "c:\users\pcadmin\documents\keshtech\dsml\kidney-disease-classification-deep-learning-project\src\cnnClassifier\components\data_ingestion.py", line 31, in download_file
    raise e
  File "c:\users\pcadmin\documents\keshtech\dsml\kidney-disease-classification-deep-learning-project\src\cnnClassifier\components\data_ingestion.py", line 26, in download_file
    gdown.download(prefix+file_id,zip_download_dir)
  File "C:\Users\PCAdmin\.conda\envs\kidney\lib\site-packages\gdown\download.py", line 368, in download
    for chunk in res.iter_content(chunk_size=CHUNK_SIZE):
  File "C:\Users\PCAdmin\.conda\envs\kidney\lib\site-packages\requests\models.py", line 822, in generate
    raise ChunkedEncodingError(e)
requests.exceptions.ChunkedEncodingError: ("Connection broken: ConnectionAbortedError(10053, 'An established connection was aborted by the software in your host machine', None, 10053, None)", ConnectionAbortedError(10053, 'An established connection was aborted by the software in your host machine', None, 10053, None))
[2025-03-03 23:38:19,149: INFO: main: >>>>>> stage Data Ingestion stage started <<<<<<]
[2025-03-03 23:38:19,150: INFO: common: yaml file: config\config.yaml loaded successfully]
[2025-03-03 23:38:19,152: INFO: common: yaml file: params.yaml loaded successfully]
[2025-03-03 23:38:19,152: INFO: common: created directory at: artifacts]
[2025-03-03 23:38:19,153: INFO: common: created directory at: artifacts/data_ingestion]
[2025-03-03 23:38:19,154: INFO: data_ingestion: Downloading data from https://drive.google.com/file/d/1vlhZ5c7abUKF8xXERIw6m9Te8fW7ohw3/view?usp=sharing into file artifacts/data_ingestion/data.zip]
[2025-03-03 23:38:53,769: ERROR: main: ("Connection broken: ConnectionAbortedError(10053, 'An established connection was aborted by the software in your host machine', None, 10053, None)", ConnectionAbortedError(10053, 'An established connection was aborted by the software in your host machine', None, 10053, None))]
Traceback (most recent call last):
  File "C:\Users\PCAdmin\.conda\envs\kidney\lib\site-packages\urllib3\response.py", line 748, in _error_catcher
    yield
  File "C:\Users\PCAdmin\.conda\envs\kidney\lib\site-packages\urllib3\response.py", line 873, in _raw_read
    data = self._fp_read(amt, read1=read1) if not fp_closed else b""
  File "C:\Users\PCAdmin\.conda\envs\kidney\lib\site-packages\urllib3\response.py", line 856, in _fp_read
    return self._fp.read(amt) if amt is not None else self._fp.read()
  File "C:\Users\PCAdmin\.conda\envs\kidney\lib\http\client.py", line 459, in read
    n = self.readinto(b)
  File "C:\Users\PCAdmin\.conda\envs\kidney\lib\http\client.py", line 503, in readinto
    n = self.fp.readinto(b)
  File "C:\Users\PCAdmin\.conda\envs\kidney\lib\socket.py", line 681, in readinto
    return self._sock.recv_into(b)
  File "C:\Users\PCAdmin\.conda\envs\kidney\lib\ssl.py", line 1274, in recv_into
    return self.read(nbytes, buffer)
  File "C:\Users\PCAdmin\.conda\envs\kidney\lib\ssl.py", line 1132, in read
    return self._sslobj.read(len, buffer)
ConnectionAbortedError: [WinError 10053] An established connection was aborted by the software in your host machine

The above exception was the direct cause of the following exception:

Traceback (most recent call last):
  File "C:\Users\PCAdmin\.conda\envs\kidney\lib\site-packages\requests\models.py", line 820, in generate
    yield from self.raw.stream(chunk_size, decode_content=True)
  File "C:\Users\PCAdmin\.conda\envs\kidney\lib\site-packages\urllib3\response.py", line 1060, in stream
    data = self.read(amt=amt, decode_content=decode_content)
  File "C:\Users\PCAdmin\.conda\envs\kidney\lib\site-packages\urllib3\response.py", line 949, in read
    data = self._raw_read(amt)
  File "C:\Users\PCAdmin\.conda\envs\kidney\lib\site-packages\urllib3\response.py", line 902, in _raw_read
    self._fp.close()
  File "C:\Users\PCAdmin\.conda\envs\kidney\lib\contextlib.py", line 131, in __exit__
    self.gen.throw(type, value, traceback)
  File "C:\Users\PCAdmin\.conda\envs\kidney\lib\site-packages\urllib3\response.py", line 775, in _error_catcher
    raise ProtocolError(f"Connection broken: {e!r}", e) from e
urllib3.exceptions.ProtocolError: ("Connection broken: ConnectionAbortedError(10053, 'An established connection was aborted by the software in your host machine', None, 10053, None)", ConnectionAbortedError(10053, 'An established connection was aborted by the software in your host machine', None, 10053, None))

During handling of the above exception, another exception occurred:

Traceback (most recent call last):
  File "main.py", line 8, in <module>
    data_ingestion.main()
  File "c:\users\pcadmin\documents\keshtech\dsml\kidney-disease-classification-deep-learning-project\src\cnnClassifier\pipeline\stage_01_data_ingestion.py", line 15, in main
    data_ingestion.download_file()
  File "c:\users\pcadmin\documents\keshtech\dsml\kidney-disease-classification-deep-learning-project\src\cnnClassifier\components\data_ingestion.py", line 31, in download_file
    raise e
  File "c:\users\pcadmin\documents\keshtech\dsml\kidney-disease-classification-deep-learning-project\src\cnnClassifier\components\data_ingestion.py", line 26, in download_file
    gdown.download(prefix+file_id,zip_download_dir)
  File "C:\Users\PCAdmin\.conda\envs\kidney\lib\site-packages\gdown\download.py", line 368, in download
    for chunk in res.iter_content(chunk_size=CHUNK_SIZE):
  File "C:\Users\PCAdmin\.conda\envs\kidney\lib\site-packages\requests\models.py", line 822, in generate
    raise ChunkedEncodingError(e)
requests.exceptions.ChunkedEncodingError: ("Connection broken: ConnectionAbortedError(10053, 'An established connection was aborted by the software in your host machine', None, 10053, None)", ConnectionAbortedError(10053, 'An established connection was aborted by the software in your host machine', None, 10053, None))
[2025-03-03 23:39:44,005: INFO: main: >>>>>> stage Data Ingestion stage started <<<<<<]
[2025-03-03 23:39:44,007: INFO: common: yaml file: config\config.yaml loaded successfully]
[2025-03-03 23:39:44,008: INFO: common: yaml file: params.yaml loaded successfully]
[2025-03-03 23:39:44,009: INFO: common: created directory at: artifacts]
[2025-03-03 23:39:44,009: INFO: common: created directory at: artifacts/data_ingestion]
[2025-03-03 23:39:44,010: INFO: data_ingestion: Downloading data from https://drive.google.com/file/d/1vlhZ5c7abUKF8xXERIw6m9Te8fW7ohw3/view?usp=sharing into file artifacts/data_ingestion/data.zip]
[2025-03-03 23:40:18,555: ERROR: main: ("Connection broken: ConnectionAbortedError(10053, 'An established connection was aborted by the software in your host machine', None, 10053, None)", ConnectionAbortedError(10053, 'An established connection was aborted by the software in your host machine', None, 10053, None))]
Traceback (most recent call last):
  File "C:\Users\PCAdmin\.conda\envs\kidney\lib\site-packages\urllib3\response.py", line 748, in _error_catcher
    yield
  File "C:\Users\PCAdmin\.conda\envs\kidney\lib\site-packages\urllib3\response.py", line 873, in _raw_read
    data = self._fp_read(amt, read1=read1) if not fp_closed else b""
  File "C:\Users\PCAdmin\.conda\envs\kidney\lib\site-packages\urllib3\response.py", line 856, in _fp_read
    return self._fp.read(amt) if amt is not None else self._fp.read()
  File "C:\Users\PCAdmin\.conda\envs\kidney\lib\http\client.py", line 459, in read
    n = self.readinto(b)
  File "C:\Users\PCAdmin\.conda\envs\kidney\lib\http\client.py", line 503, in readinto
    n = self.fp.readinto(b)
  File "C:\Users\PCAdmin\.conda\envs\kidney\lib\socket.py", line 681, in readinto
    return self._sock.recv_into(b)
  File "C:\Users\PCAdmin\.conda\envs\kidney\lib\ssl.py", line 1274, in recv_into
    return self.read(nbytes, buffer)
  File "C:\Users\PCAdmin\.conda\envs\kidney\lib\ssl.py", line 1132, in read
    return self._sslobj.read(len, buffer)
ConnectionAbortedError: [WinError 10053] An established connection was aborted by the software in your host machine

The above exception was the direct cause of the following exception:

Traceback (most recent call last):
  File "C:\Users\PCAdmin\.conda\envs\kidney\lib\site-packages\requests\models.py", line 820, in generate
    yield from self.raw.stream(chunk_size, decode_content=True)
  File "C:\Users\PCAdmin\.conda\envs\kidney\lib\site-packages\urllib3\response.py", line 1060, in stream
    data = self.read(amt=amt, decode_content=decode_content)
  File "C:\Users\PCAdmin\.conda\envs\kidney\lib\site-packages\urllib3\response.py", line 949, in read
    data = self._raw_read(amt)
  File "C:\Users\PCAdmin\.conda\envs\kidney\lib\site-packages\urllib3\response.py", line 902, in _raw_read
    self._fp.close()
  File "C:\Users\PCAdmin\.conda\envs\kidney\lib\contextlib.py", line 131, in __exit__
    self.gen.throw(type, value, traceback)
  File "C:\Users\PCAdmin\.conda\envs\kidney\lib\site-packages\urllib3\response.py", line 775, in _error_catcher
    raise ProtocolError(f"Connection broken: {e!r}", e) from e
urllib3.exceptions.ProtocolError: ("Connection broken: ConnectionAbortedError(10053, 'An established connection was aborted by the software in your host machine', None, 10053, None)", ConnectionAbortedError(10053, 'An established connection was aborted by the software in your host machine', None, 10053, None))

During handling of the above exception, another exception occurred:

Traceback (most recent call last):
  File "main.py", line 8, in <module>
    data_ingestion.main()
  File "c:\users\pcadmin\documents\keshtech\dsml\kidney-disease-classification-deep-learning-project\src\cnnClassifier\pipeline\stage_01_data_ingestion.py", line 15, in main
    data_ingestion.download_file()
  File "c:\users\pcadmin\documents\keshtech\dsml\kidney-disease-classification-deep-learning-project\src\cnnClassifier\components\data_ingestion.py", line 31, in download_file
    raise e
  File "c:\users\pcadmin\documents\keshtech\dsml\kidney-disease-classification-deep-learning-project\src\cnnClassifier\components\data_ingestion.py", line 26, in download_file
    gdown.download(prefix+file_id,zip_download_dir)
  File "C:\Users\PCAdmin\.conda\envs\kidney\lib\site-packages\gdown\download.py", line 368, in download
    for chunk in res.iter_content(chunk_size=CHUNK_SIZE):
  File "C:\Users\PCAdmin\.conda\envs\kidney\lib\site-packages\requests\models.py", line 822, in generate
    raise ChunkedEncodingError(e)
requests.exceptions.ChunkedEncodingError: ("Connection broken: ConnectionAbortedError(10053, 'An established connection was aborted by the software in your host machine', None, 10053, None)", ConnectionAbortedError(10053, 'An established connection was aborted by the software in your host machine', None, 10053, None))
[2025-03-03 23:42:07,457: INFO: main: >>>>>> stage Data Ingestion stage started <<<<<<]
[2025-03-03 23:42:07,458: INFO: common: yaml file: config\config.yaml loaded successfully]
[2025-03-03 23:42:07,458: INFO: common: yaml file: params.yaml loaded successfully]
[2025-03-03 23:42:07,459: INFO: common: created directory at: artifacts]
[2025-03-03 23:42:07,460: INFO: common: created directory at: artifacts/data_ingestion]
[2025-03-03 23:42:07,460: INFO: data_ingestion: Downloading data from https://drive.google.com/file/d/1vlhZ5c7abUKF8xXERIw6m9Te8fW7ohw3/view?usp=sharing into file artifacts/data_ingestion/data.zip]
[2025-03-03 23:42:22,678: INFO: data_ingestion: Downloaded data from https://drive.google.com/file/d/1vlhZ5c7abUKF8xXERIw6m9Te8fW7ohw3/view?usp=sharing into file artifacts/data_ingestion/data.zip]
[2025-03-03 23:42:24,570: INFO: main: >>>>>> stage Data Ingestion stage completed <<<<<<

x==========x]
[2025-03-06 23:07:17,891: INFO: common: yaml file: config\config.yaml loaded successfully]
[2025-03-06 23:07:17,911: INFO: common: yaml file: params.yaml loaded successfully]
[2025-03-06 23:07:17,915: INFO: common: created directory at: artifacts]
[2025-03-06 23:07:17,919: INFO: common: created directory at: artifacts/prepare_base_model]
[2025-03-06 23:18:13,168: WARNING: saving_utils: Compiled the loaded model, but the compiled metrics have yet to be built. `model.compile_metrics` will be empty until you train or evaluate the model.]
[2025-03-06 23:26:47,465: INFO: main: >>>>>> stage Data Ingestion stage started <<<<<<]
[2025-03-06 23:26:47,467: INFO: common: yaml file: config\config.yaml loaded successfully]
[2025-03-06 23:26:47,469: INFO: common: yaml file: params.yaml loaded successfully]
[2025-03-06 23:26:47,469: INFO: common: created directory at: artifacts]
[2025-03-06 23:26:47,469: INFO: common: created directory at: artifacts/data_ingestion]
[2025-03-06 23:26:47,470: INFO: data_ingestion: Downloading data from https://drive.google.com/file/d/1vlhZ5c7abUKF8xXERIw6m9Te8fW7ohw3/view?usp=sharing into file artifacts/data_ingestion/data.zip]
[2025-03-06 23:27:00,671: INFO: data_ingestion: Downloaded data from https://drive.google.com/file/d/1vlhZ5c7abUKF8xXERIw6m9Te8fW7ohw3/view?usp=sharing into file artifacts/data_ingestion/data.zip]
[2025-03-06 23:27:01,582: INFO: main: >>>>>> stage Data Ingestion stage completed <<<<<<

x==========x]
[2025-03-06 23:27:01,582: INFO: main: *******************]
[2025-03-06 23:27:01,582: INFO: main: >>>>>> stage Prepare base model started <<<<<<]
[2025-03-06 23:27:01,585: INFO: common: yaml file: config\config.yaml loaded successfully]
[2025-03-06 23:27:01,589: INFO: common: yaml file: params.yaml loaded successfully]
[2025-03-06 23:27:01,590: INFO: common: created directory at: artifacts]
[2025-03-06 23:27:01,591: INFO: common: created directory at: artifacts/prepare_base_model]
[2025-03-06 23:27:02,230: WARNING: saving_utils: Compiled the loaded model, but the compiled metrics have yet to be built. `model.compile_metrics` will be empty until you train or evaluate the model.]
[2025-03-06 23:27:02,502: INFO: main: >>>>>> stage Prepare base model completed <<<<<<

x==========x]
[2025-03-11 22:33:07,027: INFO: common: yaml file: config\config.yaml loaded successfully]
[2025-03-11 22:33:07,067: INFO: common: yaml file: params.yaml loaded successfully]
[2025-03-11 22:33:07,075: INFO: common: created directory at: artifacts]
[2025-03-11 22:33:07,082: INFO: common: created directory at: artifacts\training]
[2025-03-11 22:54:38,408: INFO: main: >>>>>> stage Data Ingestion stage started <<<<<<]
[2025-03-11 22:54:38,411: INFO: common: yaml file: config\config.yaml loaded successfully]
[2025-03-11 22:54:38,413: INFO: common: yaml file: params.yaml loaded successfully]
[2025-03-11 22:54:38,414: INFO: common: created directory at: artifacts]
[2025-03-11 22:54:38,415: INFO: common: created directory at: artifacts/data_ingestion]
[2025-03-11 22:54:38,415: INFO: data_ingestion: Downloading data from https://drive.google.com/file/d/1vlhZ5c7abUKF8xXERIw6m9Te8fW7ohw3/view?usp=sharing into file artifacts/data_ingestion/data.zip]
[2025-03-11 22:55:15,843: INFO: data_ingestion: Downloaded data from https://drive.google.com/file/d/1vlhZ5c7abUKF8xXERIw6m9Te8fW7ohw3/view?usp=sharing into file artifacts/data_ingestion/data.zip]
[2025-03-11 22:55:17,677: INFO: main: >>>>>> stage Data Ingestion stage completed <<<<<<

x==========x]
[2025-03-11 22:55:17,679: INFO: main: *******************]
[2025-03-11 22:55:17,679: INFO: main: >>>>>> stage Prepare base model started <<<<<<]
[2025-03-11 22:55:17,685: INFO: common: yaml file: config\config.yaml loaded successfully]
[2025-03-11 22:55:17,690: INFO: common: yaml file: params.yaml loaded successfully]
[2025-03-11 22:55:17,691: INFO: common: created directory at: artifacts]
[2025-03-11 22:55:17,692: INFO: common: created directory at: artifacts/prepare_base_model]
[2025-03-11 22:55:18,958: WARNING: saving_utils: Compiled the loaded model, but the compiled metrics have yet to be built. `model.compile_metrics` will be empty until you train or evaluate the model.]
[2025-03-11 22:55:19,475: INFO: main: >>>>>> stage Prepare base model completed <<<<<<

x==========x]
[2025-03-11 22:55:19,476: INFO: main: *******************]
[2025-03-11 22:55:19,477: INFO: main: >>>>>> stage Training started <<<<<<]
[2025-03-11 22:55:19,483: INFO: common: yaml file: config\config.yaml loaded successfully]
[2025-03-11 22:55:19,487: INFO: common: yaml file: params.yaml loaded successfully]
[2025-03-11 22:55:19,489: INFO: common: created directory at: artifacts]
[2025-03-11 22:55:19,490: INFO: common: created directory at: artifacts\training]
[2025-03-11 22:57:05,783: INFO: main: >>>>>> stage Training completed <<<<<<

x==========x]
[2025-03-13 12:11:53,126: INFO: common: yaml file: config\config.yaml loaded successfully]
[2025-03-13 12:11:53,138: INFO: common: yaml file: params.yaml loaded successfully]
[2025-03-13 12:11:53,139: INFO: common: created directory at: artifacts]
[2025-03-13 12:12:11,739: INFO: common: json file saved at: scores.json]
[2025-03-13 12:12:14,145: WARNING: save: Found untraced functions such as _jit_compiled_convolution_op, _jit_compiled_convolution_op, _jit_compiled_convolution_op, _jit_compiled_convolution_op, _jit_compiled_convolution_op while saving (showing 5 of 14). These functions will not be directly callable after loading.]
[2025-03-13 12:12:14,666: INFO: builder_impl: Assets written to: C:\Users\PCAdmin\AppData\Local\Temp\tmpgmmk8r0u\model\data\model\assets]
[2025-03-13 12:59:21,777: INFO: main: >>>>>> stage Data Ingestion stage started <<<<<<]
[2025-03-13 12:59:21,780: INFO: common: yaml file: config\config.yaml loaded successfully]
[2025-03-13 12:59:21,781: INFO: common: yaml file: params.yaml loaded successfully]
[2025-03-13 12:59:21,782: INFO: common: created directory at: artifacts]
[2025-03-13 12:59:21,782: INFO: common: created directory at: artifacts/data_ingestion]
[2025-03-13 12:59:21,784: INFO: data_ingestion: Downloading data from https://drive.google.com/file/d/1vlhZ5c7abUKF8xXERIw6m9Te8fW7ohw3/view?usp=sharing into file artifacts/data_ingestion/data.zip]
[2025-03-13 13:01:19,496: INFO: data_ingestion: Downloaded data from https://drive.google.com/file/d/1vlhZ5c7abUKF8xXERIw6m9Te8fW7ohw3/view?usp=sharing into file artifacts/data_ingestion/data.zip]
[2025-03-13 13:01:20,345: INFO: main: >>>>>> stage Data Ingestion stage completed <<<<<<

x==========x]
[2025-03-13 13:01:20,345: INFO: main: *******************]
[2025-03-13 13:01:20,345: INFO: main: >>>>>> stage Prepare base model started <<<<<<]
[2025-03-13 13:01:20,347: INFO: common: yaml file: config\config.yaml loaded successfully]
[2025-03-13 13:01:20,348: INFO: common: yaml file: params.yaml loaded successfully]
[2025-03-13 13:01:20,349: INFO: common: created directory at: artifacts]
[2025-03-13 13:01:20,349: INFO: common: created directory at: artifacts/prepare_base_model]
[2025-03-13 13:01:21,016: WARNING: saving_utils: Compiled the loaded model, but the compiled metrics have yet to be built. `model.compile_metrics` will be empty until you train or evaluate the model.]
[2025-03-13 13:01:21,267: INFO: main: >>>>>> stage Prepare base model completed <<<<<<

x==========x]
[2025-03-13 13:01:21,268: INFO: main: *******************]
[2025-03-13 13:01:21,268: INFO: main: >>>>>> stage Training started <<<<<<]
[2025-03-13 13:01:21,273: INFO: common: yaml file: config\config.yaml loaded successfully]
[2025-03-13 13:01:21,275: INFO: common: yaml file: params.yaml loaded successfully]
[2025-03-13 13:01:21,276: INFO: common: created directory at: artifacts]
[2025-03-13 13:01:21,276: INFO: common: created directory at: artifacts\training]
[2025-03-13 13:02:25,996: INFO: main: >>>>>> stage Training completed <<<<<<

x==========x]
[2025-03-13 13:02:25,997: INFO: main: *******************]
[2025-03-13 13:02:25,998: INFO: main: >>>>>> stage Evaluation stage started <<<<<<]
[2025-03-13 13:02:26,004: INFO: common: yaml file: config\config.yaml loaded successfully]
[2025-03-13 13:02:26,009: INFO: common: yaml file: params.yaml loaded successfully]
[2025-03-13 13:02:26,009: INFO: common: created directory at: artifacts]
[2025-03-13 13:02:59,891: INFO: common: json file saved at: scores.json]
[2025-03-13 13:02:59,894: INFO: common: json file saved at: scores.json]
[2025-03-13 13:02:59,895: INFO: main: >>>>>> stage Evaluation stage completed <<<<<<

x==========x]
[2025-03-13 13:04:27,932: INFO: main: >>>>>> stage Data Ingestion stage started <<<<<<]
[2025-03-13 13:04:27,935: INFO: common: yaml file: config\config.yaml loaded successfully]
[2025-03-13 13:04:27,936: INFO: common: yaml file: params.yaml loaded successfully]
[2025-03-13 13:04:27,937: INFO: common: created directory at: artifacts]
[2025-03-13 13:04:27,937: INFO: common: created directory at: artifacts/data_ingestion]
[2025-03-13 13:04:27,938: INFO: data_ingestion: Downloading data from https://drive.google.com/file/d/1vlhZ5c7abUKF8xXERIw6m9Te8fW7ohw3/view?usp=sharing into file artifacts/data_ingestion/data.zip]
[2025-03-13 13:06:10,154: INFO: data_ingestion: Downloaded data from https://drive.google.com/file/d/1vlhZ5c7abUKF8xXERIw6m9Te8fW7ohw3/view?usp=sharing into file artifacts/data_ingestion/data.zip]
[2025-03-13 13:06:11,805: INFO: main: >>>>>> stage Data Ingestion stage completed <<<<<<

x==========x]
[2025-03-13 13:06:11,805: INFO: main: *******************]
[2025-03-13 13:06:11,805: INFO: main: >>>>>> stage Prepare base model started <<<<<<]
[2025-03-13 13:06:11,811: INFO: common: yaml file: config\config.yaml loaded successfully]
[2025-03-13 13:06:11,818: INFO: common: yaml file: params.yaml loaded successfully]
[2025-03-13 13:06:11,819: INFO: common: created directory at: artifacts]
[2025-03-13 13:06:11,821: INFO: common: created directory at: artifacts/prepare_base_model]
[2025-03-13 13:06:12,988: WARNING: saving_utils: Compiled the loaded model, but the compiled metrics have yet to be built. `model.compile_metrics` will be empty until you train or evaluate the model.]
[2025-03-13 13:06:13,570: INFO: main: >>>>>> stage Prepare base model completed <<<<<<

x==========x]
[2025-03-13 13:06:13,571: INFO: main: *******************]
[2025-03-13 13:06:13,571: INFO: main: >>>>>> stage Training started <<<<<<]
[2025-03-13 13:06:13,577: INFO: common: yaml file: config\config.yaml loaded successfully]
[2025-03-13 13:06:13,583: INFO: common: yaml file: params.yaml loaded successfully]
[2025-03-13 13:06:13,584: INFO: common: created directory at: artifacts]
[2025-03-13 13:06:13,586: INFO: common: created directory at: artifacts\training]
[2025-03-13 13:07:53,699: INFO: main: >>>>>> stage Training completed <<<<<<

x==========x]
[2025-03-13 13:07:53,700: INFO: main: *******************]
[2025-03-13 13:07:53,701: INFO: main: >>>>>> stage Evaluation stage started <<<<<<]
[2025-03-13 13:07:53,704: INFO: common: yaml file: config\config.yaml loaded successfully]
[2025-03-13 13:07:53,707: INFO: common: yaml file: params.yaml loaded successfully]
[2025-03-13 13:07:53,708: INFO: common: created directory at: artifacts]
[2025-03-13 13:08:25,273: INFO: common: json file saved at: scores.json]
[2025-03-13 13:08:25,275: INFO: common: json file saved at: scores.json]
[2025-03-13 13:08:29,227: WARNING: save: Found untraced functions such as _jit_compiled_convolution_op, _jit_compiled_convolution_op, _jit_compiled_convolution_op, _jit_compiled_convolution_op, _jit_compiled_convolution_op while saving (showing 5 of 14). These functions will not be directly callable after loading.]
[2025-03-13 13:08:30,778: INFO: builder_impl: Assets written to: C:\Users\PCAdmin\AppData\Local\Temp\tmpspbk2bty\model\data\model\assets]
[2025-03-13 13:08:41,258: ERROR: main: No module named 'distutils._modified']
Traceback (most recent call last):
  File "main.py", line 47, in <module>
    model_evalution.main()
  File "c:\users\pcadmin\documents\keshtech\dsml\kidney-disease-classification-deep-learning-project\src\cnnClassifier\pipeline\stage_04_model_evaluation.py", line 20, in main
    evaluation.log_into_mlflow()
  File "c:\users\pcadmin\documents\keshtech\dsml\kidney-disease-classification-deep-learning-project\src\cnnClassifier\components\model_evaluation_mlflow.py", line 73, in log_into_mlflow
    mlflow.keras.log_model(self.model, "model")
  File "C:\Users\PCAdmin\.conda\envs\kidney\lib\site-packages\mlflow\tensorflow\__init__.py", line 222, in log_model
    return Model.log(
  File "C:\Users\PCAdmin\.conda\envs\kidney\lib\site-packages\mlflow\models\model.py", line 552, in log
    mlflow.tracking.fluent.log_artifacts(local_path, mlflow_model.artifact_path)
  File "C:\Users\PCAdmin\.conda\envs\kidney\lib\site-packages\mlflow\tracking\fluent.py", line 817, in log_artifacts
    MlflowClient().log_artifacts(run_id, local_dir, artifact_path)
  File "C:\Users\PCAdmin\.conda\envs\kidney\lib\site-packages\mlflow\tracking\client.py", line 1069, in log_artifacts
    self._tracking_client.log_artifacts(run_id, local_dir, artifact_path)
  File "C:\Users\PCAdmin\.conda\envs\kidney\lib\site-packages\mlflow\tracking\_tracking_service\client.py", line 448, in log_artifacts
    self._get_artifact_repo(run_id).log_artifacts(local_dir, artifact_path)
  File "C:\Users\PCAdmin\.conda\envs\kidney\lib\site-packages\mlflow\store\artifact\local_artifact_repo.py", line 58, in log_artifacts
    dir_util.copy_tree(src=local_dir, dst=artifact_dir, preserve_mode=0, preserve_times=0)
  File "C:\Users\PCAdmin\.conda\envs\kidney\lib\site-packages\setuptools\_distutils\dir_util.py", line 155, in copy_tree
    return list(itertools.chain.from_iterable(map(copy_one, names)))
  File "C:\Users\PCAdmin\.conda\envs\kidney\lib\site-packages\setuptools\_distutils\dir_util.py", line 197, in _copy_one
    file_util.copy_file(
  File "C:\Users\PCAdmin\.conda\envs\kidney\lib\site-packages\setuptools\_distutils\file_util.py", line 104, in copy_file
    from distutils._modified import newer
ModuleNotFoundError: No module named 'distutils._modified'
[2025-03-13 13:48:58,157: INFO: main: >>>>>> stage Data Ingestion stage started <<<<<<]
[2025-03-13 13:48:58,160: INFO: common: yaml file: config\config.yaml loaded successfully]
[2025-03-13 13:48:58,162: INFO: common: yaml file: params.yaml loaded successfully]
[2025-03-13 13:48:58,163: INFO: common: created directory at: artifacts]
[2025-03-13 13:48:58,163: INFO: common: created directory at: artifacts/data_ingestion]
[2025-03-13 13:48:58,164: INFO: data_ingestion: Downloading data from https://drive.google.com/file/d/1vlhZ5c7abUKF8xXERIw6m9Te8fW7ohw3/view?usp=sharing into file artifacts/data_ingestion/data.zip]
[2025-03-13 13:49:55,227: INFO: data_ingestion: Downloaded data from https://drive.google.com/file/d/1vlhZ5c7abUKF8xXERIw6m9Te8fW7ohw3/view?usp=sharing into file artifacts/data_ingestion/data.zip]
[2025-03-13 13:49:56,894: INFO: main: >>>>>> stage Data Ingestion stage completed <<<<<<

x==========x]
[2025-03-13 13:49:56,895: INFO: main: *******************]
[2025-03-13 13:49:56,895: INFO: main: >>>>>> stage Prepare base model started <<<<<<]
[2025-03-13 13:49:56,901: INFO: common: yaml file: config\config.yaml loaded successfully]
[2025-03-13 13:49:56,908: INFO: common: yaml file: params.yaml loaded successfully]
[2025-03-13 13:49:56,910: INFO: common: created directory at: artifacts]
[2025-03-13 13:49:56,911: INFO: common: created directory at: artifacts/prepare_base_model]
[2025-03-13 13:49:58,089: WARNING: saving_utils: Compiled the loaded model, but the compiled metrics have yet to be built. `model.compile_metrics` will be empty until you train or evaluate the model.]
[2025-03-13 13:49:58,658: INFO: main: >>>>>> stage Prepare base model completed <<<<<<

x==========x]
[2025-03-13 13:49:58,659: INFO: main: *******************]
[2025-03-13 13:49:58,659: INFO: main: >>>>>> stage Training started <<<<<<]
[2025-03-13 13:49:58,667: INFO: common: yaml file: config\config.yaml loaded successfully]
[2025-03-13 13:49:58,674: INFO: common: yaml file: params.yaml loaded successfully]
[2025-03-13 13:49:58,676: INFO: common: created directory at: artifacts]
[2025-03-13 13:49:58,677: INFO: common: created directory at: artifacts\training]
[2025-03-13 13:51:38,495: INFO: main: >>>>>> stage Training completed <<<<<<

x==========x]
[2025-03-13 13:51:38,496: INFO: main: *******************]
[2025-03-13 13:51:38,497: INFO: main: >>>>>> stage Evaluation stage started <<<<<<]
[2025-03-13 13:51:38,505: INFO: common: yaml file: config\config.yaml loaded successfully]
[2025-03-13 13:51:38,511: INFO: common: yaml file: params.yaml loaded successfully]
[2025-03-13 13:51:38,512: INFO: common: created directory at: artifacts]
[2025-03-13 13:52:15,470: INFO: common: json file saved at: scores.json]
[2025-03-13 13:52:15,472: INFO: common: json file saved at: scores.json]
[2025-03-13 13:52:19,548: WARNING: save: Found untraced functions such as _jit_compiled_convolution_op, _jit_compiled_convolution_op, _jit_compiled_convolution_op, _jit_compiled_convolution_op, _jit_compiled_convolution_op while saving (showing 5 of 14). These functions will not be directly callable after loading.]
[2025-03-13 13:52:21,041: INFO: builder_impl: Assets written to: C:\Users\PCAdmin\AppData\Local\Temp\tmpiv9tv51m\model\data\model\assets]
[2025-03-13 13:52:33,389: ERROR: main: No module named 'distutils._modified']
Traceback (most recent call last):
  File "main.py", line 47, in <module>
    model_evalution.main()
  File "c:\users\pcadmin\documents\keshtech\dsml\kidney-disease-classification-deep-learning-project\src\cnnClassifier\pipeline\stage_04_model_evaluation.py", line 20, in main
    evaluation.log_into_mlflow()
  File "c:\users\pcadmin\documents\keshtech\dsml\kidney-disease-classification-deep-learning-project\src\cnnClassifier\components\model_evaluation_mlflow.py", line 73, in log_into_mlflow
    mlflow.keras.log_model(self.model, "model")
  File "C:\Users\PCAdmin\.conda\envs\kidney\lib\site-packages\mlflow\tensorflow\__init__.py", line 222, in log_model
    return Model.log(
  File "C:\Users\PCAdmin\.conda\envs\kidney\lib\site-packages\mlflow\models\model.py", line 552, in log
    mlflow.tracking.fluent.log_artifacts(local_path, mlflow_model.artifact_path)
  File "C:\Users\PCAdmin\.conda\envs\kidney\lib\site-packages\mlflow\tracking\fluent.py", line 817, in log_artifacts
    MlflowClient().log_artifacts(run_id, local_dir, artifact_path)
  File "C:\Users\PCAdmin\.conda\envs\kidney\lib\site-packages\mlflow\tracking\client.py", line 1069, in log_artifacts
    self._tracking_client.log_artifacts(run_id, local_dir, artifact_path)
  File "C:\Users\PCAdmin\.conda\envs\kidney\lib\site-packages\mlflow\tracking\_tracking_service\client.py", line 448, in log_artifacts
    self._get_artifact_repo(run_id).log_artifacts(local_dir, artifact_path)
  File "C:\Users\PCAdmin\.conda\envs\kidney\lib\site-packages\mlflow\store\artifact\local_artifact_repo.py", line 58, in log_artifacts
    dir_util.copy_tree(src=local_dir, dst=artifact_dir, preserve_mode=0, preserve_times=0)
  File "C:\Users\PCAdmin\.conda\envs\kidney\lib\site-packages\setuptools\_distutils\dir_util.py", line 155, in copy_tree
    return list(itertools.chain.from_iterable(map(copy_one, names)))
  File "C:\Users\PCAdmin\.conda\envs\kidney\lib\site-packages\setuptools\_distutils\dir_util.py", line 197, in _copy_one
    file_util.copy_file(
  File "C:\Users\PCAdmin\.conda\envs\kidney\lib\site-packages\setuptools\_distutils\file_util.py", line 104, in copy_file
    from distutils._modified import newer
ModuleNotFoundError: No module named 'distutils._modified'
[2025-03-13 13:58:40,740: INFO: main: >>>>>> stage Data Ingestion stage started <<<<<<]
[2025-03-13 13:58:40,743: INFO: common: yaml file: config\config.yaml loaded successfully]
[2025-03-13 13:58:40,745: INFO: common: yaml file: params.yaml loaded successfully]
[2025-03-13 13:58:40,745: INFO: common: created directory at: artifacts]
[2025-03-13 13:58:40,746: INFO: common: created directory at: artifacts/data_ingestion]
[2025-03-13 13:58:40,746: INFO: data_ingestion: Downloading data from https://drive.google.com/file/d/1vlhZ5c7abUKF8xXERIw6m9Te8fW7ohw3/view?usp=sharing into file artifacts/data_ingestion/data.zip]
[2025-03-13 13:59:35,179: INFO: data_ingestion: Downloaded data from https://drive.google.com/file/d/1vlhZ5c7abUKF8xXERIw6m9Te8fW7ohw3/view?usp=sharing into file artifacts/data_ingestion/data.zip]
[2025-03-13 13:59:36,901: INFO: main: >>>>>> stage Data Ingestion stage completed <<<<<<

x==========x]
[2025-03-13 13:59:36,902: INFO: main: *******************]
[2025-03-13 13:59:36,903: INFO: main: >>>>>> stage Prepare base model started <<<<<<]
[2025-03-13 13:59:36,908: INFO: common: yaml file: config\config.yaml loaded successfully]
[2025-03-13 13:59:36,912: INFO: common: yaml file: params.yaml loaded successfully]
[2025-03-13 13:59:36,914: INFO: common: created directory at: artifacts]
[2025-03-13 13:59:36,915: INFO: common: created directory at: artifacts/prepare_base_model]
[2025-03-13 13:59:38,058: WARNING: saving_utils: Compiled the loaded model, but the compiled metrics have yet to be built. `model.compile_metrics` will be empty until you train or evaluate the model.]
[2025-03-13 13:59:38,660: INFO: main: >>>>>> stage Prepare base model completed <<<<<<

x==========x]
[2025-03-13 13:59:38,661: INFO: main: *******************]
[2025-03-13 13:59:38,662: INFO: main: >>>>>> stage Training started <<<<<<]
[2025-03-13 13:59:38,668: INFO: common: yaml file: config\config.yaml loaded successfully]
[2025-03-13 13:59:38,672: INFO: common: yaml file: params.yaml loaded successfully]
[2025-03-13 13:59:38,673: INFO: common: created directory at: artifacts]
[2025-03-13 13:59:38,675: INFO: common: created directory at: artifacts\training]
[2025-03-13 14:01:29,077: INFO: main: >>>>>> stage Training completed <<<<<<

x==========x]
[2025-03-13 14:01:29,077: INFO: main: *******************]
[2025-03-13 14:01:29,078: INFO: main: >>>>>> stage Evaluation stage started <<<<<<]
[2025-03-13 14:01:29,084: INFO: common: yaml file: config\config.yaml loaded successfully]
[2025-03-13 14:01:29,089: INFO: common: yaml file: params.yaml loaded successfully]
[2025-03-13 14:01:29,090: INFO: common: created directory at: artifacts]
[2025-03-13 14:02:06,121: INFO: common: json file saved at: scores.json]
[2025-03-13 14:02:06,123: INFO: common: json file saved at: scores.json]
[2025-03-13 14:02:10,228: WARNING: save: Found untraced functions such as _jit_compiled_convolution_op, _jit_compiled_convolution_op, _jit_compiled_convolution_op, _jit_compiled_convolution_op, _jit_compiled_convolution_op while saving (showing 5 of 14). These functions will not be directly callable after loading.]
[2025-03-13 14:02:11,871: INFO: builder_impl: Assets written to: C:\Users\PCAdmin\AppData\Local\Temp\tmpbchojahe\model\data\model\assets]
[2025-03-13 14:02:26,052: ERROR: main: No module named 'distutils._modified']
Traceback (most recent call last):
  File "main.py", line 47, in <module>
    model_evalution.main()
  File "c:\users\pcadmin\documents\keshtech\dsml\kidney-disease-classification-deep-learning-project\src\cnnClassifier\pipeline\stage_04_model_evaluation.py", line 20, in main
    evaluation.log_into_mlflow()
  File "c:\users\pcadmin\documents\keshtech\dsml\kidney-disease-classification-deep-learning-project\src\cnnClassifier\components\model_evaluation_mlflow.py", line 73, in log_into_mlflow
    mlflow.keras.log_model(self.model, "model")
  File "C:\Users\PCAdmin\.conda\envs\kidney\lib\site-packages\mlflow\tensorflow\__init__.py", line 222, in log_model
    return Model.log(
  File "C:\Users\PCAdmin\.conda\envs\kidney\lib\site-packages\mlflow\models\model.py", line 552, in log
    mlflow.tracking.fluent.log_artifacts(local_path, mlflow_model.artifact_path)
  File "C:\Users\PCAdmin\.conda\envs\kidney\lib\site-packages\mlflow\tracking\fluent.py", line 817, in log_artifacts
    MlflowClient().log_artifacts(run_id, local_dir, artifact_path)
  File "C:\Users\PCAdmin\.conda\envs\kidney\lib\site-packages\mlflow\tracking\client.py", line 1069, in log_artifacts
    self._tracking_client.log_artifacts(run_id, local_dir, artifact_path)
  File "C:\Users\PCAdmin\.conda\envs\kidney\lib\site-packages\mlflow\tracking\_tracking_service\client.py", line 448, in log_artifacts
    self._get_artifact_repo(run_id).log_artifacts(local_dir, artifact_path)
  File "C:\Users\PCAdmin\.conda\envs\kidney\lib\site-packages\mlflow\store\artifact\local_artifact_repo.py", line 58, in log_artifacts
    dir_util.copy_tree(src=local_dir, dst=artifact_dir, preserve_mode=0, preserve_times=0)
  File "C:\Users\PCAdmin\.conda\envs\kidney\lib\site-packages\setuptools\_distutils\dir_util.py", line 155, in copy_tree
    return list(itertools.chain.from_iterable(map(copy_one, names)))
  File "C:\Users\PCAdmin\.conda\envs\kidney\lib\site-packages\setuptools\_distutils\dir_util.py", line 197, in _copy_one
    file_util.copy_file(
  File "C:\Users\PCAdmin\.conda\envs\kidney\lib\site-packages\setuptools\_distutils\file_util.py", line 104, in copy_file
    from distutils._modified import newer
ModuleNotFoundError: No module named 'distutils._modified'
[2025-03-13 14:04:02,307: INFO: common: yaml file: config\config.yaml loaded successfully]
[2025-03-13 14:04:02,315: INFO: common: yaml file: params.yaml loaded successfully]
[2025-03-13 14:04:02,319: INFO: common: created directory at: artifacts]
[2025-03-13 14:04:26,327: INFO: common: json file saved at: scores.json]
[2025-03-13 14:04:45,688: WARNING: connectionpool: Retrying (Retry(total=4, connect=5, read=4, redirect=5, status=5)) after connection broken by 'ProtocolError('Connection aborted.', ConnectionResetError(10054, 'An existing connection was forcibly closed by the remote host', None, 10054, None))': /Keshtech2002/Kidney-Disease-Classification-Deep-Learning-Project.mlflow/api/2.0/mlflow/runs/create]
[2025-03-13 14:04:50,478: WARNING: save: Found untraced functions such as _jit_compiled_convolution_op, _jit_compiled_convolution_op, _jit_compiled_convolution_op, _jit_compiled_convolution_op, _jit_compiled_convolution_op while saving (showing 5 of 14). These functions will not be directly callable after loading.]
[2025-03-13 14:04:52,098: INFO: builder_impl: Assets written to: C:\Users\PCAdmin\AppData\Local\Temp\tmphmp1kjvx\model\data\model\assets]
[2025-03-13 14:12:53,649: INFO: _client: HTTP Request: GET https://dagshub.com/api/v1/user "HTTP/1.1 200 OK"]
[2025-03-13 14:12:53,656: INFO: helpers: Accessing as Keshtech2002]
[2025-03-13 14:12:54,336: INFO: _client: HTTP Request: GET https://dagshub.com/api/v1/repos/Keshtech2002/Kidney-Disease-Classification-Deep-Learning-Project "HTTP/1.1 200 OK"]
[2025-03-13 14:12:55,055: INFO: _client: HTTP Request: GET https://dagshub.com/api/v1/user "HTTP/1.1 200 OK"]
[2025-03-13 14:12:55,060: INFO: helpers: Initialized MLflow to track repo "Keshtech2002/Kidney-Disease-Classification-Deep-Learning-Project"]
[2025-03-13 14:12:55,061: INFO: helpers: Repository Keshtech2002/Kidney-Disease-Classification-Deep-Learning-Project initialized!]
[2025-03-13 14:12:55,062: INFO: main: >>>>>> stage Data Ingestion stage started <<<<<<]
[2025-03-13 14:12:55,068: INFO: common: yaml file: config\config.yaml loaded successfully]
[2025-03-13 14:12:55,073: INFO: common: yaml file: params.yaml loaded successfully]
[2025-03-13 14:12:55,074: INFO: common: created directory at: artifacts]
[2025-03-13 14:12:55,076: INFO: common: created directory at: artifacts/data_ingestion]
[2025-03-13 14:12:55,077: INFO: data_ingestion: Downloading data from https://drive.google.com/file/d/1vlhZ5c7abUKF8xXERIw6m9Te8fW7ohw3/view?usp=sharing into file artifacts/data_ingestion/data.zip]
[2025-03-13 14:13:16,518: INFO: data_ingestion: Downloaded data from https://drive.google.com/file/d/1vlhZ5c7abUKF8xXERIw6m9Te8fW7ohw3/view?usp=sharing into file artifacts/data_ingestion/data.zip]
[2025-03-13 14:13:18,134: INFO: main: >>>>>> stage Data Ingestion stage completed <<<<<<

x==========x]
[2025-03-13 14:13:18,135: INFO: main: *******************]
[2025-03-13 14:13:18,135: INFO: main: >>>>>> stage Prepare base model started <<<<<<]
[2025-03-13 14:13:18,143: INFO: common: yaml file: config\config.yaml loaded successfully]
[2025-03-13 14:13:18,150: INFO: common: yaml file: params.yaml loaded successfully]
[2025-03-13 14:13:18,151: INFO: common: created directory at: artifacts]
[2025-03-13 14:13:18,153: INFO: common: created directory at: artifacts/prepare_base_model]
[2025-03-13 14:13:19,351: WARNING: saving_utils: Compiled the loaded model, but the compiled metrics have yet to be built. `model.compile_metrics` will be empty until you train or evaluate the model.]
[2025-03-13 14:13:20,024: INFO: main: >>>>>> stage Prepare base model completed <<<<<<

x==========x]
[2025-03-13 14:13:20,025: INFO: main: *******************]
[2025-03-13 14:13:20,025: INFO: main: >>>>>> stage Training started <<<<<<]
[2025-03-13 14:13:20,031: INFO: common: yaml file: config\config.yaml loaded successfully]
[2025-03-13 14:13:20,034: INFO: common: yaml file: params.yaml loaded successfully]
[2025-03-13 14:13:20,035: INFO: common: created directory at: artifacts]
[2025-03-13 14:13:20,036: INFO: common: created directory at: artifacts\training]
[2025-03-13 14:15:01,563: INFO: main: >>>>>> stage Training completed <<<<<<

x==========x]
[2025-03-13 14:15:01,563: INFO: main: *******************]
[2025-03-13 14:15:01,564: INFO: main: >>>>>> stage Evaluation stage started <<<<<<]
[2025-03-13 14:15:01,572: INFO: common: yaml file: config\config.yaml loaded successfully]
[2025-03-13 14:15:01,576: INFO: common: yaml file: params.yaml loaded successfully]
[2025-03-13 14:15:01,579: INFO: common: created directory at: artifacts]
[2025-03-13 14:15:35,048: INFO: common: json file saved at: scores.json]
[2025-03-13 14:15:35,050: INFO: common: json file saved at: scores.json]
[2025-03-13 14:15:40,357: WARNING: save: Found untraced functions such as _jit_compiled_convolution_op, _jit_compiled_convolution_op, _jit_compiled_convolution_op, _jit_compiled_convolution_op, _jit_compiled_convolution_op while saving (showing 5 of 14). These functions will not be directly callable after loading.]
[2025-03-13 14:15:41,842: INFO: builder_impl: Assets written to: C:\Users\PCAdmin\AppData\Local\Temp\tmpsr0t9zeg\model\data\model\assets]
[2025-03-13 14:17:30,886: INFO: main: >>>>>> stage Evaluation stage completed <<<<<<

x==========x]
[2025-03-13 14:27:47,568: INFO: _client: HTTP Request: GET https://dagshub.com/api/v1/user "HTTP/1.1 200 OK"]
[2025-03-13 14:27:47,581: INFO: helpers: Accessing as Keshtech2002]
[2025-03-13 14:27:48,215: INFO: _client: HTTP Request: GET https://dagshub.com/api/v1/repos/Keshtech2002/Kidney-Disease-Classification-Deep-Learning-Project "HTTP/1.1 200 OK"]
[2025-03-13 14:27:48,818: INFO: _client: HTTP Request: GET https://dagshub.com/api/v1/user "HTTP/1.1 200 OK"]
[2025-03-13 14:27:48,825: INFO: helpers: Initialized MLflow to track repo "Keshtech2002/Kidney-Disease-Classification-Deep-Learning-Project"]
[2025-03-13 14:27:48,827: INFO: helpers: Repository Keshtech2002/Kidney-Disease-Classification-Deep-Learning-Project initialized!]
[2025-03-13 14:27:48,828: INFO: main: >>>>>> stage Data Ingestion stage started <<<<<<]
[2025-03-13 14:27:48,835: INFO: common: yaml file: config\config.yaml loaded successfully]
[2025-03-13 14:27:48,851: INFO: common: yaml file: params.yaml loaded successfully]
[2025-03-13 14:27:48,852: INFO: common: created directory at: artifacts]
[2025-03-13 14:27:48,852: INFO: common: created directory at: artifacts/data_ingestion]
[2025-03-13 14:27:48,852: INFO: data_ingestion: Downloading data from https://drive.google.com/file/d/1vlhZ5c7abUKF8xXERIw6m9Te8fW7ohw3/view?usp=sharing into file artifacts/data_ingestion/data.zip]
[2025-03-13 14:37:14,862: INFO: _client: HTTP Request: GET https://dagshub.com/api/v1/user "HTTP/1.1 200 OK"]
[2025-03-13 14:37:14,878: INFO: helpers: Accessing as Keshtech2002]
[2025-03-13 14:37:17,360: INFO: _client: HTTP Request: GET https://dagshub.com/api/v1/repos/Keshtech2002/Kidney-Disease-Classification-Deep-Learning-Project "HTTP/1.1 200 OK"]
[2025-03-13 14:37:18,909: INFO: _client: HTTP Request: GET https://dagshub.com/api/v1/user "HTTP/1.1 200 OK"]
[2025-03-13 14:37:18,912: INFO: helpers: Initialized MLflow to track repo "Keshtech2002/Kidney-Disease-Classification-Deep-Learning-Project"]
[2025-03-13 14:37:18,913: INFO: helpers: Repository Keshtech2002/Kidney-Disease-Classification-Deep-Learning-Project initialized!]
[2025-03-13 14:37:18,913: INFO: main: >>>>>> stage Data Ingestion stage started <<<<<<]
[2025-03-13 14:37:18,921: INFO: common: yaml file: config\config.yaml loaded successfully]
[2025-03-13 14:37:18,925: INFO: common: yaml file: params.yaml loaded successfully]
[2025-03-13 14:37:18,927: INFO: common: created directory at: artifacts]
[2025-03-13 14:37:18,928: INFO: common: created directory at: artifacts/data_ingestion]
[2025-03-13 14:37:18,929: INFO: data_ingestion: Downloading data from https://drive.google.com/file/d/1vlhZ5c7abUKF8xXERIw6m9Te8fW7ohw3/view?usp=sharing into file artifacts/data_ingestion/data.zip]
[2025-03-13 14:38:27,338: INFO: data_ingestion: Downloaded data from https://drive.google.com/file/d/1vlhZ5c7abUKF8xXERIw6m9Te8fW7ohw3/view?usp=sharing into file artifacts/data_ingestion/data.zip]
[2025-03-13 14:38:28,967: INFO: main: >>>>>> stage Data Ingestion stage completed <<<<<<

x==========x]
[2025-03-13 14:38:28,968: INFO: main: *******************]
[2025-03-13 14:38:28,968: INFO: main: >>>>>> stage Prepare base model started <<<<<<]
[2025-03-13 14:38:28,974: INFO: common: yaml file: config\config.yaml loaded successfully]
[2025-03-13 14:38:28,980: INFO: common: yaml file: params.yaml loaded successfully]
[2025-03-13 14:38:28,981: INFO: common: created directory at: artifacts]
[2025-03-13 14:38:28,982: INFO: common: created directory at: artifacts/prepare_base_model]
[2025-03-13 14:38:30,153: WARNING: saving_utils: Compiled the loaded model, but the compiled metrics have yet to be built. `model.compile_metrics` will be empty until you train or evaluate the model.]
[2025-03-13 14:38:30,657: INFO: main: >>>>>> stage Prepare base model completed <<<<<<

x==========x]
[2025-03-13 14:38:30,657: INFO: main: *******************]
[2025-03-13 14:38:30,658: INFO: main: >>>>>> stage Training started <<<<<<]
[2025-03-13 14:38:30,664: INFO: common: yaml file: config\config.yaml loaded successfully]
[2025-03-13 14:38:30,668: INFO: common: yaml file: params.yaml loaded successfully]
[2025-03-13 14:38:30,669: INFO: common: created directory at: artifacts]
[2025-03-13 14:38:30,670: INFO: common: created directory at: artifacts\training]
[2025-03-13 14:41:42,982: INFO: main: >>>>>> stage Training completed <<<<<<

x==========x]
[2025-03-13 14:41:42,983: INFO: main: *******************]
[2025-03-13 14:41:42,984: INFO: main: >>>>>> stage Evaluation stage started <<<<<<]
[2025-03-13 14:41:42,991: INFO: common: yaml file: config\config.yaml loaded successfully]
[2025-03-13 14:41:42,995: INFO: common: yaml file: params.yaml loaded successfully]
[2025-03-13 14:41:42,996: INFO: common: created directory at: artifacts]
[2025-03-13 14:42:14,527: INFO: common: json file saved at: scores.json]
[2025-03-13 14:42:14,529: INFO: common: json file saved at: scores.json]
[2025-03-13 14:42:19,975: WARNING: save: Found untraced functions such as _jit_compiled_convolution_op, _jit_compiled_convolution_op, _jit_compiled_convolution_op, _jit_compiled_convolution_op, _jit_compiled_convolution_op while saving (showing 5 of 14). These functions will not be directly callable after loading.]
[2025-03-13 14:42:21,563: INFO: builder_impl: Assets written to: C:\Users\PCAdmin\AppData\Local\Temp\tmplnbgltj9\model\data\model\assets]
[2025-03-13 14:44:26,656: INFO: main: >>>>>> stage Evaluation stage completed <<<<<<

x==========x]
[2025-03-13 14:44:55,543: INFO: _client: HTTP Request: GET https://dagshub.com/api/v1/user "HTTP/1.1 200 OK"]
[2025-03-13 14:44:55,551: INFO: helpers: Accessing as Keshtech2002]
[2025-03-13 14:44:56,957: INFO: _client: HTTP Request: GET https://dagshub.com/api/v1/repos/Keshtech2002/Kidney-Disease-Classification-Deep-Learning-Project "HTTP/1.1 200 OK"]
[2025-03-13 14:44:58,274: INFO: _client: HTTP Request: GET https://dagshub.com/api/v1/user "HTTP/1.1 200 OK"]
[2025-03-13 14:44:58,281: INFO: helpers: Initialized MLflow to track repo "Keshtech2002/Kidney-Disease-Classification-Deep-Learning-Project"]
[2025-03-13 14:44:58,283: INFO: helpers: Repository Keshtech2002/Kidney-Disease-Classification-Deep-Learning-Project initialized!]
[2025-03-13 14:44:58,283: INFO: main: >>>>>> stage Data Ingestion stage started <<<<<<]
[2025-03-13 14:44:58,290: INFO: common: yaml file: config\config.yaml loaded successfully]
[2025-03-13 14:44:58,311: INFO: common: yaml file: params.yaml loaded successfully]
[2025-03-13 14:44:58,312: INFO: common: created directory at: artifacts]
[2025-03-13 14:44:58,314: INFO: common: created directory at: artifacts/data_ingestion]
[2025-03-13 14:44:58,315: INFO: data_ingestion: Downloading data from https://drive.google.com/file/d/1vlhZ5c7abUKF8xXERIw6m9Te8fW7ohw3/view?usp=sharing into file artifacts/data_ingestion/data.zip]
[2025-03-13 14:45:25,925: INFO: data_ingestion: Downloaded data from https://drive.google.com/file/d/1vlhZ5c7abUKF8xXERIw6m9Te8fW7ohw3/view?usp=sharing into file artifacts/data_ingestion/data.zip]
[2025-03-13 14:45:27,104: INFO: main: >>>>>> stage Data Ingestion stage completed <<<<<<

x==========x]
[2025-03-13 14:45:27,104: INFO: main: *******************]
[2025-03-13 14:45:27,105: INFO: main: >>>>>> stage Prepare base model started <<<<<<]
[2025-03-13 14:45:27,107: INFO: common: yaml file: config\config.yaml loaded successfully]
[2025-03-13 14:45:27,109: INFO: common: yaml file: params.yaml loaded successfully]
[2025-03-13 14:45:27,109: INFO: common: created directory at: artifacts]
[2025-03-13 14:45:27,110: INFO: common: created directory at: artifacts/prepare_base_model]
[2025-03-13 14:45:27,947: WARNING: saving_utils: Compiled the loaded model, but the compiled metrics have yet to be built. `model.compile_metrics` will be empty until you train or evaluate the model.]
[2025-03-13 14:45:28,544: INFO: main: >>>>>> stage Prepare base model completed <<<<<<

x==========x]
[2025-03-13 14:45:28,545: INFO: main: *******************]
[2025-03-13 14:45:28,545: INFO: main: >>>>>> stage Training started <<<<<<]
[2025-03-13 14:45:28,551: INFO: common: yaml file: config\config.yaml loaded successfully]
[2025-03-13 14:45:28,555: INFO: common: yaml file: params.yaml loaded successfully]
[2025-03-13 14:45:28,556: INFO: common: created directory at: artifacts]
[2025-03-13 14:45:28,556: INFO: common: created directory at: artifacts\training]
[2025-03-13 14:50:16,992: INFO: main: >>>>>> stage Training completed <<<<<<

x==========x]
[2025-03-13 14:50:16,993: INFO: main: *******************]
[2025-03-13 14:50:16,994: INFO: main: >>>>>> stage Evaluation stage started <<<<<<]
[2025-03-13 14:50:17,000: INFO: common: yaml file: config\config.yaml loaded successfully]
[2025-03-13 14:50:17,006: INFO: common: yaml file: params.yaml loaded successfully]
[2025-03-13 14:50:17,007: INFO: common: created directory at: artifacts]
[2025-03-13 14:50:49,253: INFO: common: json file saved at: scores.json]
[2025-03-13 14:50:49,255: INFO: common: json file saved at: scores.json]
[2025-03-13 14:50:55,799: WARNING: save: Found untraced functions such as _jit_compiled_convolution_op, _jit_compiled_convolution_op, _jit_compiled_convolution_op, _jit_compiled_convolution_op, _jit_compiled_convolution_op while saving (showing 5 of 14). These functions will not be directly callable after loading.]
[2025-03-13 14:50:57,495: INFO: builder_impl: Assets written to: C:\Users\PCAdmin\AppData\Local\Temp\tmpkw6gnoyi\model\data\model\assets]
[2025-03-13 14:52:35,416: INFO: main: >>>>>> stage Evaluation stage completed <<<<<<

x==========x]
[2025-03-16 07:20:42,202: INFO: stage_01_data_ingestion: >>>>>> stage Data Ingestion stage started <<<<<<]
[2025-03-16 07:20:42,206: INFO: common: yaml file: config\config.yaml loaded successfully]
[2025-03-16 07:20:42,208: INFO: common: yaml file: params.yaml loaded successfully]
[2025-03-16 07:20:42,209: INFO: common: created directory at: artifacts]
[2025-03-16 07:20:42,210: INFO: common: created directory at: artifacts/data_ingestion]
[2025-03-16 07:20:42,211: INFO: data_ingestion: Downloading data from https://drive.google.com/file/d/1vlhZ5c7abUKF8xXERIw6m9Te8fW7ohw3/view?usp=sharing into file artifacts/data_ingestion/data.zip]
[2025-03-16 07:21:04,310: INFO: data_ingestion: Downloaded data from https://drive.google.com/file/d/1vlhZ5c7abUKF8xXERIw6m9Te8fW7ohw3/view?usp=sharing into file artifacts/data_ingestion/data.zip]
[2025-03-16 07:21:06,355: INFO: stage_01_data_ingestion: >>>>>> stage Data Ingestion stage completed <<<<<<

x==========x]
[2025-03-16 07:25:22,351: INFO: stage_01_data_ingestion: >>>>>> stage Data Ingestion stage started <<<<<<]
[2025-03-16 07:25:22,373: INFO: common: yaml file: config\config.yaml loaded successfully]
[2025-03-16 07:25:22,375: INFO: common: yaml file: params.yaml loaded successfully]
[2025-03-16 07:25:22,375: INFO: common: created directory at: artifacts]
[2025-03-16 07:25:22,376: INFO: common: created directory at: artifacts/data_ingestion]
[2025-03-16 07:25:22,378: INFO: data_ingestion: Downloading data from https://drive.google.com/file/d/1vlhZ5c7abUKF8xXERIw6m9Te8fW7ohw3/view?usp=sharing into file artifacts/data_ingestion/data.zip]
[2025-03-16 07:25:44,364: INFO: data_ingestion: Downloaded data from https://drive.google.com/file/d/1vlhZ5c7abUKF8xXERIw6m9Te8fW7ohw3/view?usp=sharing into file artifacts/data_ingestion/data.zip]
[2025-03-16 07:25:46,014: INFO: stage_01_data_ingestion: >>>>>> stage Data Ingestion stage completed <<<<<<

x==========x]
[2025-03-16 07:35:46,478: INFO: stage_01_data_ingestion: >>>>>> stage Data Ingestion stage started <<<<<<]
[2025-03-16 07:35:46,482: INFO: common: yaml file: config\config.yaml loaded successfully]
[2025-03-16 07:35:46,485: INFO: common: yaml file: params.yaml loaded successfully]
[2025-03-16 07:35:46,486: INFO: common: created directory at: artifacts]
[2025-03-16 07:35:46,487: INFO: common: created directory at: artifacts/data_ingestion]
[2025-03-16 07:35:46,487: INFO: data_ingestion: Downloading data from https://drive.google.com/file/d/1vlhZ5c7abUKF8xXERIw6m9Te8fW7ohw3/view?usp=sharing into file artifacts/data_ingestion/data.zip]
[2025-03-16 07:36:06,152: INFO: data_ingestion: Downloaded data from https://drive.google.com/file/d/1vlhZ5c7abUKF8xXERIw6m9Te8fW7ohw3/view?usp=sharing into file artifacts/data_ingestion/data.zip]
[2025-03-16 07:36:07,793: INFO: stage_01_data_ingestion: >>>>>> stage Data Ingestion stage completed <<<<<<

x==========x]
[2025-03-16 07:40:42,727: INFO: stage_01_data_ingestion: >>>>>> stage Data Ingestion stage started <<<<<<]
[2025-03-16 07:40:42,730: INFO: common: yaml file: config\config.yaml loaded successfully]
[2025-03-16 07:40:42,733: INFO: common: yaml file: params.yaml loaded successfully]
[2025-03-16 07:40:42,733: INFO: common: created directory at: artifacts]
[2025-03-16 07:40:42,734: INFO: common: created directory at: artifacts/data_ingestion]
[2025-03-16 07:40:42,734: INFO: data_ingestion: Downloading data from https://drive.google.com/file/d/1vlhZ5c7abUKF8xXERIw6m9Te8fW7ohw3/view?usp=sharing into file artifacts/data_ingestion/data.zip]
[2025-03-16 07:41:01,435: INFO: data_ingestion: Downloaded data from https://drive.google.com/file/d/1vlhZ5c7abUKF8xXERIw6m9Te8fW7ohw3/view?usp=sharing into file artifacts/data_ingestion/data.zip]
[2025-03-16 07:41:03,675: INFO: stage_01_data_ingestion: >>>>>> stage Data Ingestion stage completed <<<<<<

x==========x]
[2025-03-16 12:14:28,881: INFO: _client: HTTP Request: GET https://dagshub.com/api/v1/user "HTTP/1.1 200 OK"]
[2025-03-16 12:14:28,903: INFO: helpers: Accessing as Keshtech2002]
[2025-03-16 12:14:31,036: INFO: _client: HTTP Request: GET https://dagshub.com/api/v1/repos/Keshtech2002/Kidney-Disease-Classification-Deep-Learning-Project "HTTP/1.1 200 OK"]
[2025-03-16 12:14:32,375: INFO: _client: HTTP Request: GET https://dagshub.com/api/v1/user "HTTP/1.1 200 OK"]
[2025-03-16 12:14:32,381: INFO: helpers: Initialized MLflow to track repo "Keshtech2002/Kidney-Disease-Classification-Deep-Learning-Project"]
[2025-03-16 12:14:32,384: INFO: helpers: Repository Keshtech2002/Kidney-Disease-Classification-Deep-Learning-Project initialized!]
[2025-03-16 12:14:32,384: INFO: main: >>>>>> stage Data Ingestion stage started <<<<<<]
[2025-03-16 12:14:32,406: INFO: common: yaml file: config\config.yaml loaded successfully]
[2025-03-16 12:14:32,432: INFO: common: yaml file: params.yaml loaded successfully]
[2025-03-16 12:14:32,435: INFO: common: created directory at: artifacts]
[2025-03-16 12:14:32,436: INFO: common: created directory at: artifacts/data_ingestion]
[2025-03-16 12:14:32,437: INFO: data_ingestion: Downloading data from https://drive.google.com/file/d/1vlhZ5c7abUKF8xXERIw6m9Te8fW7ohw3/view?usp=sharing into file artifacts/data_ingestion/data.zip]
[2025-03-16 12:14:56,379: INFO: data_ingestion: Downloaded data from https://drive.google.com/file/d/1vlhZ5c7abUKF8xXERIw6m9Te8fW7ohw3/view?usp=sharing into file artifacts/data_ingestion/data.zip]
[2025-03-16 12:14:58,080: INFO: main: >>>>>> stage Data Ingestion stage completed <<<<<<

x==========x]
[2025-03-16 12:14:58,081: INFO: main: *******************]
[2025-03-16 12:14:58,081: INFO: main: >>>>>> stage Prepare base model started <<<<<<]
[2025-03-16 12:14:58,092: INFO: common: yaml file: config\config.yaml loaded successfully]
[2025-03-16 12:14:58,097: INFO: common: yaml file: params.yaml loaded successfully]
[2025-03-16 12:14:58,098: INFO: common: created directory at: artifacts]
[2025-03-16 12:14:58,100: INFO: common: created directory at: artifacts/prepare_base_model]
[2025-03-16 12:14:59,478: WARNING: saving_utils: Compiled the loaded model, but the compiled metrics have yet to be built. `model.compile_metrics` will be empty until you train or evaluate the model.]
[2025-03-16 12:15:00,037: INFO: main: >>>>>> stage Prepare base model completed <<<<<<

x==========x]
[2025-03-16 12:15:00,038: INFO: main: *******************]
[2025-03-16 12:15:00,039: INFO: main: >>>>>> stage Training started <<<<<<]
[2025-03-16 12:15:00,055: INFO: common: yaml file: config\config.yaml loaded successfully]
[2025-03-16 12:15:00,060: INFO: common: yaml file: params.yaml loaded successfully]
[2025-03-16 12:15:00,062: INFO: common: created directory at: artifacts]
[2025-03-16 12:15:00,064: INFO: common: created directory at: artifacts\training]
[2025-03-16 12:20:07,459: INFO: main: >>>>>> stage Training completed <<<<<<

x==========x]
[2025-03-16 12:20:07,460: INFO: main: *******************]
[2025-03-16 12:20:07,460: INFO: main: >>>>>> stage Evaluation stage started <<<<<<]
[2025-03-16 12:20:07,467: INFO: common: yaml file: config\config.yaml loaded successfully]
[2025-03-16 12:20:07,474: INFO: common: yaml file: params.yaml loaded successfully]
[2025-03-16 12:20:07,475: INFO: common: created directory at: artifacts]
[2025-03-16 12:20:39,506: INFO: common: json file saved at: scores.json]
[2025-03-16 12:20:39,507: INFO: common: json file saved at: scores.json]
[2025-03-16 12:20:39,507: INFO: main: >>>>>> stage Evaluation stage completed <<<<<<

x==========x]
[2025-03-16 12:35:34,734: INFO: stage_01_data_ingestion: >>>>>> stage Data Ingestion stage started <<<<<<]
[2025-03-16 12:35:34,736: INFO: common: yaml file: config\config.yaml loaded successfully]
[2025-03-16 12:35:34,737: INFO: common: yaml file: params.yaml loaded successfully]
[2025-03-16 12:35:34,738: INFO: common: created directory at: artifacts]
[2025-03-16 12:35:34,738: INFO: common: created directory at: artifacts/data_ingestion]
[2025-03-16 12:35:34,738: INFO: data_ingestion: Downloading data from https://drive.google.com/file/d/1vlhZ5c7abUKF8xXERIw6m9Te8fW7ohw3/view?usp=sharing into file artifacts/data_ingestion/data.zip]
[2025-03-16 12:35:56,736: INFO: data_ingestion: Downloaded data from https://drive.google.com/file/d/1vlhZ5c7abUKF8xXERIw6m9Te8fW7ohw3/view?usp=sharing into file artifacts/data_ingestion/data.zip]
[2025-03-16 12:35:58,624: INFO: stage_01_data_ingestion: >>>>>> stage Data Ingestion stage completed <<<<<<

x==========x]
[2025-03-16 12:43:58,404: INFO: stage_01_data_ingestion: >>>>>> stage Data Ingestion stage started <<<<<<]
[2025-03-16 12:43:58,407: INFO: common: yaml file: config\config.yaml loaded successfully]
[2025-03-16 12:43:58,408: INFO: common: yaml file: params.yaml loaded successfully]
[2025-03-16 12:43:58,409: INFO: common: created directory at: artifacts]
[2025-03-16 12:43:58,409: INFO: common: created directory at: artifacts/data_ingestion]
[2025-03-16 12:43:58,410: INFO: data_ingestion: Downloading data from https://drive.google.com/file/d/1vlhZ5c7abUKF8xXERIw6m9Te8fW7ohw3/view?usp=sharing into file artifacts/data_ingestion/data.zip]
[2025-03-16 12:44:21,486: INFO: data_ingestion: Downloaded data from https://drive.google.com/file/d/1vlhZ5c7abUKF8xXERIw6m9Te8fW7ohw3/view?usp=sharing into file artifacts/data_ingestion/data.zip]
[2025-03-16 12:44:23,394: INFO: stage_01_data_ingestion: >>>>>> stage Data Ingestion stage completed <<<<<<

x==========x]
[2025-03-16 12:58:20,231: INFO: stage_01_data_ingestion: >>>>>> stage Data Ingestion stage started <<<<<<]
[2025-03-16 12:58:20,234: INFO: common: yaml file: config\config.yaml loaded successfully]
[2025-03-16 12:58:20,236: INFO: common: yaml file: params.yaml loaded successfully]
[2025-03-16 12:58:20,236: INFO: common: created directory at: artifacts]
[2025-03-16 12:58:20,237: INFO: common: created directory at: artifacts/data_ingestion]
[2025-03-16 12:58:20,237: INFO: data_ingestion: Downloading data from https://drive.google.com/file/d/1vlhZ5c7abUKF8xXERIw6m9Te8fW7ohw3/view?usp=sharing into file artifacts/data_ingestion/data.zip]
[2025-03-16 12:58:37,612: INFO: data_ingestion: Downloaded data from https://drive.google.com/file/d/1vlhZ5c7abUKF8xXERIw6m9Te8fW7ohw3/view?usp=sharing into file artifacts/data_ingestion/data.zip]
[2025-03-16 12:58:38,326: INFO: stage_01_data_ingestion: >>>>>> stage Data Ingestion stage completed <<<<<<

x==========x]
[2025-03-16 13:01:59,516: INFO: stage_01_data_ingestion: >>>>>> stage Data Ingestion stage started <<<<<<]
[2025-03-16 13:01:59,518: INFO: common: yaml file: config\config.yaml loaded successfully]
[2025-03-16 13:01:59,519: INFO: common: yaml file: params.yaml loaded successfully]
[2025-03-16 13:01:59,520: INFO: common: created directory at: artifacts]
[2025-03-16 13:01:59,520: INFO: common: created directory at: artifacts/data_ingestion]
[2025-03-16 13:01:59,521: INFO: data_ingestion: Downloading data from https://drive.google.com/file/d/1vlhZ5c7abUKF8xXERIw6m9Te8fW7ohw3/view?usp=sharing into file artifacts/data_ingestion/data.zip]
[2025-03-16 13:02:18,754: INFO: data_ingestion: Downloaded data from https://drive.google.com/file/d/1vlhZ5c7abUKF8xXERIw6m9Te8fW7ohw3/view?usp=sharing into file artifacts/data_ingestion/data.zip]
[2025-03-16 13:02:19,424: INFO: stage_01_data_ingestion: >>>>>> stage Data Ingestion stage completed <<<<<<

x==========x]
[2025-03-16 13:03:54,717: INFO: stage_01_data_ingestion: >>>>>> stage Data Ingestion stage started <<<<<<]
[2025-03-16 13:03:54,720: INFO: common: yaml file: config\config.yaml loaded successfully]
[2025-03-16 13:03:54,721: INFO: common: yaml file: params.yaml loaded successfully]
[2025-03-16 13:03:54,722: INFO: common: created directory at: artifacts]
[2025-03-16 13:03:54,722: INFO: common: created directory at: artifacts/data_ingestion]
[2025-03-16 13:03:54,723: INFO: data_ingestion: Downloading data from https://drive.google.com/file/d/1vlhZ5c7abUKF8xXERIw6m9Te8fW7ohw3/view?usp=sharing into file artifacts/data_ingestion/data.zip]
[2025-03-16 13:04:11,603: INFO: data_ingestion: Downloaded data from https://drive.google.com/file/d/1vlhZ5c7abUKF8xXERIw6m9Te8fW7ohw3/view?usp=sharing into file artifacts/data_ingestion/data.zip]
[2025-03-16 13:04:12,282: INFO: stage_01_data_ingestion: >>>>>> stage Data Ingestion stage completed <<<<<<

x==========x]
[2025-03-16 14:10:54,820: INFO: stage_01_data_ingestion: >>>>>> stage Data Ingestion stage started <<<<<<]
[2025-03-16 14:10:54,822: INFO: common: yaml file: config\config.yaml loaded successfully]
[2025-03-16 14:10:54,825: INFO: common: yaml file: params.yaml loaded successfully]
[2025-03-16 14:10:54,825: INFO: common: created directory at: artifacts]
[2025-03-16 14:10:54,826: INFO: common: created directory at: artifacts/data_ingestion]
[2025-03-16 14:10:54,826: INFO: data_ingestion: Downloading data from https://drive.google.com/file/d/1vlhZ5c7abUKF8xXERIw6m9Te8fW7ohw3/view?usp=sharing into file artifacts/data_ingestion/data.zip]
[2025-03-16 14:11:11,119: INFO: data_ingestion: Downloaded data from https://drive.google.com/file/d/1vlhZ5c7abUKF8xXERIw6m9Te8fW7ohw3/view?usp=sharing into file artifacts/data_ingestion/data.zip]
[2025-03-16 14:11:11,750: INFO: stage_01_data_ingestion: >>>>>> stage Data Ingestion stage completed <<<<<<

x==========x]
[2025-03-16 14:27:36,879: INFO: stage_01_data_ingestion: >>>>>> stage Data Ingestion stage started <<<<<<]
[2025-03-16 14:27:36,881: INFO: common: yaml file: config\config.yaml loaded successfully]
[2025-03-16 14:27:36,883: INFO: common: yaml file: params.yaml loaded successfully]
[2025-03-16 14:27:36,884: INFO: common: created directory at: artifacts]
[2025-03-16 14:27:36,884: INFO: common: created directory at: artifacts/data_ingestion]
[2025-03-16 14:27:36,885: INFO: data_ingestion: Downloading data from https://drive.google.com/file/d/1vlhZ5c7abUKF8xXERIw6m9Te8fW7ohw3/view?usp=sharing into file artifacts/data_ingestion/data.zip]
[2025-03-16 14:27:53,663: INFO: data_ingestion: Downloaded data from https://drive.google.com/file/d/1vlhZ5c7abUKF8xXERIw6m9Te8fW7ohw3/view?usp=sharing into file artifacts/data_ingestion/data.zip]
[2025-03-16 14:27:54,309: INFO: stage_01_data_ingestion: >>>>>> stage Data Ingestion stage completed <<<<<<

x==========x]
[2025-03-16 14:33:20,216: INFO: stage_01_data_ingestion: >>>>>> stage Data Ingestion stage started <<<<<<]
[2025-03-16 14:33:20,218: INFO: common: yaml file: config\config.yaml loaded successfully]
[2025-03-16 14:33:20,220: INFO: common: yaml file: params.yaml loaded successfully]
[2025-03-16 14:33:20,220: INFO: common: created directory at: artifacts]
[2025-03-16 14:33:20,221: INFO: common: created directory at: artifacts/data_ingestion]
[2025-03-16 14:33:20,221: INFO: data_ingestion: Downloading data from https://drive.google.com/file/d/1vlhZ5c7abUKF8xXERIw6m9Te8fW7ohw3/view?usp=sharing into file artifacts/data_ingestion/data.zip]
[2025-03-16 14:33:37,698: INFO: data_ingestion: Downloaded data from https://drive.google.com/file/d/1vlhZ5c7abUKF8xXERIw6m9Te8fW7ohw3/view?usp=sharing into file artifacts/data_ingestion/data.zip]
[2025-03-16 14:33:38,348: INFO: stage_01_data_ingestion: >>>>>> stage Data Ingestion stage completed <<<<<<

x==========x]
[2025-03-16 14:36:37,122: INFO: stage_01_data_ingestion: >>>>>> stage Data Ingestion stage started <<<<<<]
[2025-03-16 14:36:37,123: INFO: common: yaml file: config\config.yaml loaded successfully]
[2025-03-16 14:36:37,125: INFO: common: yaml file: params.yaml loaded successfully]
[2025-03-16 14:36:37,125: INFO: common: created directory at: artifacts]
[2025-03-16 14:36:37,126: INFO: common: created directory at: artifacts/data_ingestion]
[2025-03-16 14:36:37,126: INFO: data_ingestion: Downloading data from https://drive.google.com/file/d/1vlhZ5c7abUKF8xXERIw6m9Te8fW7ohw3/view?usp=sharing into file artifacts/data_ingestion/data.zip]
[2025-03-16 14:37:07,469: INFO: data_ingestion: Downloaded data from https://drive.google.com/file/d/1vlhZ5c7abUKF8xXERIw6m9Te8fW7ohw3/view?usp=sharing into file artifacts/data_ingestion/data.zip]
[2025-03-16 14:37:08,422: INFO: stage_01_data_ingestion: >>>>>> stage Data Ingestion stage completed <<<<<<

x==========x]
[2025-03-16 14:41:17,367: INFO: stage_01_data_ingestion: >>>>>> stage Data Ingestion stage started <<<<<<]
[2025-03-16 14:41:17,369: INFO: common: yaml file: config\config.yaml loaded successfully]
[2025-03-16 14:41:17,371: INFO: common: yaml file: params.yaml loaded successfully]
[2025-03-16 14:41:17,372: INFO: common: created directory at: artifacts]
[2025-03-16 14:41:17,372: INFO: common: created directory at: artifacts/data_ingestion]
[2025-03-16 14:41:17,373: INFO: data_ingestion: Downloading data from https://drive.google.com/file/d/1vlhZ5c7abUKF8xXERIw6m9Te8fW7ohw3/view?usp=sharing into file artifacts/data_ingestion/data.zip]
[2025-03-16 14:41:35,683: INFO: data_ingestion: Downloaded data from https://drive.google.com/file/d/1vlhZ5c7abUKF8xXERIw6m9Te8fW7ohw3/view?usp=sharing into file artifacts/data_ingestion/data.zip]
[2025-03-16 14:41:36,267: INFO: stage_01_data_ingestion: >>>>>> stage Data Ingestion stage completed <<<<<<

x==========x]
[2025-03-16 14:50:04,334: INFO: stage_01_data_ingestion: >>>>>> stage Data Ingestion stage started <<<<<<]
[2025-03-16 14:50:04,335: INFO: common: yaml file: config\config.yaml loaded successfully]
[2025-03-16 14:50:04,338: INFO: common: yaml file: params.yaml loaded successfully]
[2025-03-16 14:50:04,339: INFO: common: created directory at: artifacts]
[2025-03-16 14:50:04,340: INFO: common: created directory at: artifacts/data_ingestion]
[2025-03-16 14:50:04,341: INFO: data_ingestion: Downloading data from https://drive.google.com/file/d/1vlhZ5c7abUKF8xXERIw6m9Te8fW7ohw3/view?usp=sharing into file artifacts/data_ingestion/data.zip]
[2025-03-16 14:50:38,500: INFO: data_ingestion: Downloaded data from https://drive.google.com/file/d/1vlhZ5c7abUKF8xXERIw6m9Te8fW7ohw3/view?usp=sharing into file artifacts/data_ingestion/data.zip]
[2025-03-16 14:50:39,090: INFO: stage_01_data_ingestion: >>>>>> stage Data Ingestion stage completed <<<<<<

x==========x]
[2025-03-16 15:01:15,505: INFO: stage_01_data_ingestion: >>>>>> stage Data Ingestion stage started <<<<<<]
[2025-03-16 15:01:15,507: INFO: common: yaml file: config\config.yaml loaded successfully]
[2025-03-16 15:01:15,508: INFO: common: yaml file: params.yaml loaded successfully]
[2025-03-16 15:01:15,509: INFO: common: created directory at: artifacts]
[2025-03-16 15:01:15,510: INFO: common: created directory at: artifacts/data_ingestion]
[2025-03-16 15:01:15,511: INFO: data_ingestion: Downloading data from https://drive.google.com/file/d/1vlhZ5c7abUKF8xXERIw6m9Te8fW7ohw3/view?usp=sharing into file artifacts/data_ingestion/data.zip]
[2025-03-16 15:01:35,321: INFO: data_ingestion: Downloaded data from https://drive.google.com/file/d/1vlhZ5c7abUKF8xXERIw6m9Te8fW7ohw3/view?usp=sharing into file artifacts/data_ingestion/data.zip]
[2025-03-16 15:01:37,199: INFO: stage_01_data_ingestion: >>>>>> stage Data Ingestion stage completed <<<<<<

x==========x]
[2025-03-16 17:08:32,626: INFO: _internal: [31m[1mWARNING: This is a development server. Do not use it in a production deployment. Use a production WSGI server instead.[0m
 * Running on all addresses (0.0.0.0)
 * Running on http://127.0.0.1:8080
 * Running on http://192.168.246.214:8080]
[2025-03-16 17:08:32,628: INFO: _internal: [33mPress CTRL+C to quit[0m]
[2025-03-16 17:08:41,336: INFO: _internal: 127.0.0.1 - - [16/Mar/2025 17:08:41] "GET / HTTP/1.1" 200 -]
[2025-03-16 17:11:39,150: ERROR: app: Exception on /predict [POST]]
Traceback (most recent call last):
  File "C:\Users\PCAdmin\.conda\envs\kidney\lib\site-packages\flask\app.py", line 2190, in wsgi_app
    response = self.full_dispatch_request()
  File "C:\Users\PCAdmin\.conda\envs\kidney\lib\site-packages\flask\app.py", line 1486, in full_dispatch_request
    rv = self.handle_user_exception(e)
  File "C:\Users\PCAdmin\.conda\envs\kidney\lib\site-packages\flask_cors\extension.py", line 194, in wrapped_function
    return cors_after_request(app.make_response(f(*args, **kwargs)))
  File "C:\Users\PCAdmin\.conda\envs\kidney\lib\site-packages\flask\app.py", line 1484, in full_dispatch_request
    rv = self.dispatch_request()
  File "C:\Users\PCAdmin\.conda\envs\kidney\lib\site-packages\flask\app.py", line 1469, in dispatch_request
    return self.ensure_sync(self.view_functions[rule.endpoint])(**view_args)
  File "C:\Users\PCAdmin\.conda\envs\kidney\lib\site-packages\flask_cors\decorator.py", line 130, in wrapped_function
    resp = make_response(f(*args, **kwargs))
  File "app.py", line 44, in predictRoute
    result = clApp.classifier.predict()
  File "c:\users\pcadmin\documents\keshtech\dsml\kidney-disease-classification-deep-learning-project\src\cnnClassifier\pipeline\prediction.py", line 16, in predict
    model = load_model(os.path.join("model", "model.h5"))
  File "C:\Users\PCAdmin\.conda\envs\kidney\lib\site-packages\keras\saving\saving_api.py", line 212, in load_model
    return legacy_sm_saving_lib.load_model(
  File "C:\Users\PCAdmin\.conda\envs\kidney\lib\site-packages\keras\utils\traceback_utils.py", line 70, in error_handler
    raise e.with_traceback(filtered_tb) from None
  File "C:\Users\PCAdmin\.conda\envs\kidney\lib\site-packages\keras\saving\legacy\save.py", line 230, in load_model
    raise IOError(
OSError: No file or directory found at model\model.h5
[2025-03-16 17:11:39,311: INFO: _internal: 127.0.0.1 - - [16/Mar/2025 17:11:39] "[35m[1mPOST /predict HTTP/1.1[0m" 500 -]
[2025-03-16 17:13:36,713: INFO: _client: HTTP Request: GET https://dagshub.com/api/v1/user "HTTP/1.1 200 OK"]
[2025-03-16 17:13:36,732: INFO: helpers: Accessing as Keshtech2002]
[2025-03-16 17:13:38,015: INFO: _client: HTTP Request: GET https://dagshub.com/api/v1/repos/Keshtech2002/Kidney-Disease-Classification-Deep-Learning-Project "HTTP/1.1 200 OK"]
[2025-03-16 17:13:39,015: INFO: _client: HTTP Request: GET https://dagshub.com/api/v1/user "HTTP/1.1 200 OK"]
[2025-03-16 17:13:39,020: INFO: helpers: Initialized MLflow to track repo "Keshtech2002/Kidney-Disease-Classification-Deep-Learning-Project"]
[2025-03-16 17:13:39,022: INFO: helpers: Repository Keshtech2002/Kidney-Disease-Classification-Deep-Learning-Project initialized!]
[2025-03-16 17:13:39,023: INFO: main: >>>>>> stage Data Ingestion stage started <<<<<<]
[2025-03-16 17:13:39,039: INFO: common: yaml file: config\config.yaml loaded successfully]
[2025-03-16 17:13:39,051: INFO: common: yaml file: params.yaml loaded successfully]
[2025-03-16 17:13:39,053: INFO: common: created directory at: artifacts]
[2025-03-16 17:13:39,055: INFO: common: created directory at: artifacts/data_ingestion]
[2025-03-16 17:13:39,056: INFO: data_ingestion: Downloading data from https://drive.google.com/file/d/1vlhZ5c7abUKF8xXERIw6m9Te8fW7ohw3/view?usp=sharing into file artifacts/data_ingestion/data.zip]
[2025-03-16 17:13:55,705: INFO: data_ingestion: Downloaded data from https://drive.google.com/file/d/1vlhZ5c7abUKF8xXERIw6m9Te8fW7ohw3/view?usp=sharing into file artifacts/data_ingestion/data.zip]
[2025-03-16 17:13:57,524: INFO: main: >>>>>> stage Data Ingestion stage completed <<<<<<

x==========x]
[2025-03-16 17:13:57,524: INFO: main: *******************]
[2025-03-16 17:13:57,525: INFO: main: >>>>>> stage Prepare base model started <<<<<<]
[2025-03-16 17:13:57,531: INFO: common: yaml file: config\config.yaml loaded successfully]
[2025-03-16 17:13:57,535: INFO: common: yaml file: params.yaml loaded successfully]
[2025-03-16 17:13:57,536: INFO: common: created directory at: artifacts]
[2025-03-16 17:13:57,538: INFO: common: created directory at: artifacts/prepare_base_model]
[2025-03-16 17:13:58,897: WARNING: saving_utils: Compiled the loaded model, but the compiled metrics have yet to be built. `model.compile_metrics` will be empty until you train or evaluate the model.]
[2025-03-16 17:13:59,409: INFO: main: >>>>>> stage Prepare base model completed <<<<<<

x==========x]
[2025-03-16 17:13:59,409: INFO: main: *******************]
[2025-03-16 17:13:59,410: INFO: main: >>>>>> stage Training started <<<<<<]
[2025-03-16 17:13:59,416: INFO: common: yaml file: config\config.yaml loaded successfully]
[2025-03-16 17:13:59,420: INFO: common: yaml file: params.yaml loaded successfully]
[2025-03-16 17:13:59,421: INFO: common: created directory at: artifacts]
[2025-03-16 17:13:59,423: INFO: common: created directory at: artifacts\training]
[2025-03-16 17:19:01,233: INFO: main: >>>>>> stage Training completed <<<<<<

x==========x]
[2025-03-16 17:19:01,234: INFO: main: *******************]
[2025-03-16 17:19:01,235: INFO: main: >>>>>> stage Evaluation stage started <<<<<<]
[2025-03-16 17:19:01,242: INFO: common: yaml file: config\config.yaml loaded successfully]
[2025-03-16 17:19:01,248: INFO: common: yaml file: params.yaml loaded successfully]
[2025-03-16 17:19:01,250: INFO: common: created directory at: artifacts]
[2025-03-16 17:19:35,078: INFO: common: json file saved at: scores.json]
[2025-03-16 17:19:35,081: INFO: common: json file saved at: scores.json]
[2025-03-16 17:19:35,082: INFO: main: >>>>>> stage Evaluation stage completed <<<<<<

x==========x]
[2025-03-16 17:19:51,618: INFO: _internal: [31m[1mWARNING: This is a development server. Do not use it in a production deployment. Use a production WSGI server instead.[0m
 * Running on all addresses (0.0.0.0)
 * Running on http://127.0.0.1:8080
 * Running on http://192.168.246.214:8080]
[2025-03-16 17:19:51,618: INFO: _internal: [33mPress CTRL+C to quit[0m]
[2025-03-16 17:20:03,331: INFO: _internal: 127.0.0.1 - - [16/Mar/2025 17:20:03] "GET / HTTP/1.1" 200 -]
[2025-03-16 17:20:10,861: ERROR: app: Exception on /predict [POST]]
Traceback (most recent call last):
  File "C:\Users\PCAdmin\.conda\envs\kidney\lib\site-packages\flask\app.py", line 2190, in wsgi_app
    response = self.full_dispatch_request()
  File "C:\Users\PCAdmin\.conda\envs\kidney\lib\site-packages\flask\app.py", line 1486, in full_dispatch_request
    rv = self.handle_user_exception(e)
  File "C:\Users\PCAdmin\.conda\envs\kidney\lib\site-packages\flask_cors\extension.py", line 194, in wrapped_function
    return cors_after_request(app.make_response(f(*args, **kwargs)))
  File "C:\Users\PCAdmin\.conda\envs\kidney\lib\site-packages\flask\app.py", line 1484, in full_dispatch_request
    rv = self.dispatch_request()
  File "C:\Users\PCAdmin\.conda\envs\kidney\lib\site-packages\flask\app.py", line 1469, in dispatch_request
    return self.ensure_sync(self.view_functions[rule.endpoint])(**view_args)
  File "C:\Users\PCAdmin\.conda\envs\kidney\lib\site-packages\flask_cors\decorator.py", line 130, in wrapped_function
    resp = make_response(f(*args, **kwargs))
  File "app.py", line 44, in predictRoute
    result = clApp.classifier.predict()
  File "c:\users\pcadmin\documents\keshtech\dsml\kidney-disease-classification-deep-learning-project\src\cnnClassifier\pipeline\prediction.py", line 16, in predict
    model = load_model(os.path.join("model", "model.h5"))
  File "C:\Users\PCAdmin\.conda\envs\kidney\lib\site-packages\keras\saving\saving_api.py", line 212, in load_model
    return legacy_sm_saving_lib.load_model(
  File "C:\Users\PCAdmin\.conda\envs\kidney\lib\site-packages\keras\utils\traceback_utils.py", line 70, in error_handler
    raise e.with_traceback(filtered_tb) from None
  File "C:\Users\PCAdmin\.conda\envs\kidney\lib\site-packages\keras\saving\legacy\save.py", line 230, in load_model
    raise IOError(
OSError: No file or directory found at model\model.h5
[2025-03-16 17:20:10,869: INFO: _internal: 127.0.0.1 - - [16/Mar/2025 17:20:10] "[35m[1mPOST /predict HTTP/1.1[0m" 500 -]
[2025-03-16 17:25:44,683: INFO: stage_01_data_ingestion: >>>>>> stage Data Ingestion stage started <<<<<<]
[2025-03-16 17:25:44,688: INFO: common: yaml file: config\config.yaml loaded successfully]
[2025-03-16 17:25:44,691: INFO: common: yaml file: params.yaml loaded successfully]
[2025-03-16 17:25:44,691: INFO: common: created directory at: artifacts]
[2025-03-16 17:25:44,692: INFO: common: created directory at: artifacts/data_ingestion]
[2025-03-16 17:25:44,692: INFO: data_ingestion: Downloading data from https://drive.google.com/file/d/1vlhZ5c7abUKF8xXERIw6m9Te8fW7ohw3/view?usp=sharing into file artifacts/data_ingestion/data.zip]
[2025-03-16 17:26:06,269: INFO: data_ingestion: Downloaded data from https://drive.google.com/file/d/1vlhZ5c7abUKF8xXERIw6m9Te8fW7ohw3/view?usp=sharing into file artifacts/data_ingestion/data.zip]
[2025-03-16 17:26:07,777: INFO: stage_01_data_ingestion: >>>>>> stage Data Ingestion stage completed <<<<<<

x==========x]
[2025-03-16 17:30:29,449: INFO: stage_01_data_ingestion: >>>>>> stage Data Ingestion stage started <<<<<<]
[2025-03-16 17:30:29,451: INFO: common: yaml file: config\config.yaml loaded successfully]
[2025-03-16 17:30:29,453: INFO: common: yaml file: params.yaml loaded successfully]
[2025-03-16 17:30:29,453: INFO: common: created directory at: artifacts]
[2025-03-16 17:30:29,453: INFO: common: created directory at: artifacts/data_ingestion]
[2025-03-16 17:30:29,454: INFO: data_ingestion: Downloading data from https://drive.google.com/file/d/1vlhZ5c7abUKF8xXERIw6m9Te8fW7ohw3/view?usp=sharing into file artifacts/data_ingestion/data.zip]
[2025-03-16 17:31:08,825: INFO: data_ingestion: Downloaded data from https://drive.google.com/file/d/1vlhZ5c7abUKF8xXERIw6m9Te8fW7ohw3/view?usp=sharing into file artifacts/data_ingestion/data.zip]
[2025-03-16 17:31:10,781: INFO: stage_01_data_ingestion: >>>>>> stage Data Ingestion stage completed <<<<<<

x==========x]
[2025-03-16 17:38:10,989: INFO: _client: HTTP Request: GET https://dagshub.com/api/v1/user "HTTP/1.1 200 OK"]
[2025-03-16 17:38:11,005: INFO: helpers: Accessing as Keshtech2002]
[2025-03-16 17:38:12,072: INFO: _client: HTTP Request: GET https://dagshub.com/api/v1/repos/Keshtech2002/Kidney-Disease-Classification-Deep-Learning-Project "HTTP/1.1 200 OK"]
[2025-03-16 17:38:13,289: INFO: _client: HTTP Request: GET https://dagshub.com/api/v1/user "HTTP/1.1 200 OK"]
[2025-03-16 17:38:13,295: INFO: helpers: Initialized MLflow to track repo "Keshtech2002/Kidney-Disease-Classification-Deep-Learning-Project"]
[2025-03-16 17:38:13,297: INFO: helpers: Repository Keshtech2002/Kidney-Disease-Classification-Deep-Learning-Project initialized!]
[2025-03-16 17:38:13,298: INFO: main: >>>>>> stage Data Ingestion stage started <<<<<<]
[2025-03-16 17:38:13,304: INFO: common: yaml file: config\config.yaml loaded successfully]
[2025-03-16 17:38:13,310: INFO: common: yaml file: params.yaml loaded successfully]
[2025-03-16 17:38:13,312: INFO: common: created directory at: artifacts]
[2025-03-16 17:38:13,312: INFO: common: created directory at: artifacts/data_ingestion]
[2025-03-16 17:38:13,314: INFO: data_ingestion: Downloading data from https://drive.google.com/file/d/1vlhZ5c7abUKF8xXERIw6m9Te8fW7ohw3/view?usp=sharing into file artifacts/data_ingestion/data.zip]
[2025-03-16 17:38:33,456: INFO: data_ingestion: Downloaded data from https://drive.google.com/file/d/1vlhZ5c7abUKF8xXERIw6m9Te8fW7ohw3/view?usp=sharing into file artifacts/data_ingestion/data.zip]
[2025-03-16 17:38:35,420: INFO: main: >>>>>> stage Data Ingestion stage completed <<<<<<

x==========x]
[2025-03-16 17:38:35,421: INFO: main: *******************]
[2025-03-16 17:38:35,421: INFO: main: >>>>>> stage Prepare base model started <<<<<<]
[2025-03-16 17:38:35,432: INFO: common: yaml file: config\config.yaml loaded successfully]
[2025-03-16 17:38:35,439: INFO: common: yaml file: params.yaml loaded successfully]
[2025-03-16 17:38:35,441: INFO: common: created directory at: artifacts]
[2025-03-16 17:38:35,442: INFO: common: created directory at: artifacts/prepare_base_model]
[2025-03-16 17:38:36,737: WARNING: saving_utils: Compiled the loaded model, but the compiled metrics have yet to be built. `model.compile_metrics` will be empty until you train or evaluate the model.]
[2025-03-16 17:38:37,325: INFO: main: >>>>>> stage Prepare base model completed <<<<<<

x==========x]
[2025-03-16 17:38:37,326: INFO: main: *******************]
[2025-03-16 17:38:37,326: INFO: main: >>>>>> stage Training started <<<<<<]
[2025-03-16 17:38:37,334: INFO: common: yaml file: config\config.yaml loaded successfully]
[2025-03-16 17:38:37,338: INFO: common: yaml file: params.yaml loaded successfully]
[2025-03-16 17:38:37,339: INFO: common: created directory at: artifacts]
[2025-03-16 17:38:37,340: INFO: common: created directory at: artifacts\training]
[2025-03-16 17:44:16,514: INFO: main: >>>>>> stage Training completed <<<<<<

x==========x]
[2025-03-16 17:44:16,515: INFO: main: *******************]
[2025-03-16 17:44:16,516: INFO: main: >>>>>> stage Evaluation stage started <<<<<<]
[2025-03-16 17:44:16,526: INFO: common: yaml file: config\config.yaml loaded successfully]
[2025-03-16 17:44:16,531: INFO: common: yaml file: params.yaml loaded successfully]
[2025-03-16 17:44:16,535: INFO: common: created directory at: artifacts]
[2025-03-16 17:44:53,519: INFO: common: json file saved at: scores.json]
[2025-03-16 17:44:53,523: INFO: common: json file saved at: scores.json]
[2025-03-16 17:44:53,524: INFO: main: >>>>>> stage Evaluation stage completed <<<<<<

x==========x]
[2025-03-16 17:50:18,803: INFO: stage_01_data_ingestion: >>>>>> stage Data Ingestion stage started <<<<<<]
[2025-03-16 17:50:18,806: INFO: common: yaml file: config\config.yaml loaded successfully]
[2025-03-16 17:50:18,810: INFO: common: yaml file: params.yaml loaded successfully]
[2025-03-16 17:50:18,810: INFO: common: created directory at: artifacts]
[2025-03-16 17:50:18,811: INFO: common: created directory at: artifacts/data_ingestion]
[2025-03-16 17:50:18,811: INFO: data_ingestion: Downloading data from https://drive.google.com/file/d/1vlhZ5c7abUKF8xXERIw6m9Te8fW7ohw3/view?usp=sharing into file artifacts/data_ingestion/data.zip]
[2025-03-16 17:50:35,634: INFO: data_ingestion: Downloaded data from https://drive.google.com/file/d/1vlhZ5c7abUKF8xXERIw6m9Te8fW7ohw3/view?usp=sharing into file artifacts/data_ingestion/data.zip]
[2025-03-16 17:50:37,594: INFO: stage_01_data_ingestion: >>>>>> stage Data Ingestion stage completed <<<<<<

x==========x]
[2025-03-16 19:10:05,532: INFO: _internal: [31m[1mWARNING: This is a development server. Do not use it in a production deployment. Use a production WSGI server instead.[0m
 * Running on all addresses (0.0.0.0)
 * Running on http://127.0.0.1:8080
 * Running on http://192.168.137.222:8080]
[2025-03-16 19:10:05,532: INFO: _internal: [33mPress CTRL+C to quit[0m]
[2025-03-16 19:10:13,774: INFO: _internal: 127.0.0.1 - - [16/Mar/2025 19:10:13] "GET / HTTP/1.1" 200 -]
[2025-03-16 19:10:52,641: ERROR: app: Exception on /predict [POST]]
Traceback (most recent call last):
  File "C:\Users\PCAdmin\.conda\envs\kidney\lib\site-packages\flask\app.py", line 2190, in wsgi_app
    response = self.full_dispatch_request()
  File "C:\Users\PCAdmin\.conda\envs\kidney\lib\site-packages\flask\app.py", line 1486, in full_dispatch_request
    rv = self.handle_user_exception(e)
  File "C:\Users\PCAdmin\.conda\envs\kidney\lib\site-packages\flask_cors\extension.py", line 194, in wrapped_function
    return cors_after_request(app.make_response(f(*args, **kwargs)))
  File "C:\Users\PCAdmin\.conda\envs\kidney\lib\site-packages\flask\app.py", line 1484, in full_dispatch_request
    rv = self.dispatch_request()
  File "C:\Users\PCAdmin\.conda\envs\kidney\lib\site-packages\flask\app.py", line 1469, in dispatch_request
    return self.ensure_sync(self.view_functions[rule.endpoint])(**view_args)
  File "C:\Users\PCAdmin\.conda\envs\kidney\lib\site-packages\flask_cors\decorator.py", line 130, in wrapped_function
    resp = make_response(f(*args, **kwargs))
  File "app.py", line 44, in predictRoute
    result = clApp.classifier.predict()
  File "c:\users\pcadmin\documents\keshtech\dsml\kidney-disease-classification-deep-learning-project\src\cnnClassifier\pipeline\prediction.py", line 16, in predict
    model = load_model(os.path.join("model", "model.h5"))
  File "C:\Users\PCAdmin\.conda\envs\kidney\lib\site-packages\keras\saving\saving_api.py", line 212, in load_model
    return legacy_sm_saving_lib.load_model(
  File "C:\Users\PCAdmin\.conda\envs\kidney\lib\site-packages\keras\utils\traceback_utils.py", line 70, in error_handler
    raise e.with_traceback(filtered_tb) from None
  File "C:\Users\PCAdmin\.conda\envs\kidney\lib\site-packages\keras\saving\legacy\save.py", line 230, in load_model
    raise IOError(
OSError: No file or directory found at model\model.h5
[2025-03-16 19:10:52,653: INFO: _internal: 127.0.0.1 - - [16/Mar/2025 19:10:52] "[35m[1mPOST /predict HTTP/1.1[0m" 500 -]
[2025-03-16 19:14:16,876: INFO: _internal: 127.0.0.1 - - [16/Mar/2025 19:14:16] "GET / HTTP/1.1" 200 -]
[2025-03-16 19:14:22,286: ERROR: app: Exception on /predict [POST]]
Traceback (most recent call last):
  File "C:\Users\PCAdmin\.conda\envs\kidney\lib\site-packages\flask\app.py", line 2190, in wsgi_app
    response = self.full_dispatch_request()
  File "C:\Users\PCAdmin\.conda\envs\kidney\lib\site-packages\flask\app.py", line 1486, in full_dispatch_request
    rv = self.handle_user_exception(e)
  File "C:\Users\PCAdmin\.conda\envs\kidney\lib\site-packages\flask_cors\extension.py", line 194, in wrapped_function
    return cors_after_request(app.make_response(f(*args, **kwargs)))
  File "C:\Users\PCAdmin\.conda\envs\kidney\lib\site-packages\flask\app.py", line 1484, in full_dispatch_request
    rv = self.dispatch_request()
  File "C:\Users\PCAdmin\.conda\envs\kidney\lib\site-packages\flask\app.py", line 1469, in dispatch_request
    return self.ensure_sync(self.view_functions[rule.endpoint])(**view_args)
  File "C:\Users\PCAdmin\.conda\envs\kidney\lib\site-packages\flask_cors\decorator.py", line 130, in wrapped_function
    resp = make_response(f(*args, **kwargs))
  File "app.py", line 44, in predictRoute
    result = clApp.classifier.predict()
  File "c:\users\pcadmin\documents\keshtech\dsml\kidney-disease-classification-deep-learning-project\src\cnnClassifier\pipeline\prediction.py", line 16, in predict
    model = load_model(os.path.join("artifacts", "training", "model.h5"))
  File "C:\Users\PCAdmin\.conda\envs\kidney\lib\site-packages\keras\saving\saving_api.py", line 212, in load_model
    return legacy_sm_saving_lib.load_model(
  File "C:\Users\PCAdmin\.conda\envs\kidney\lib\site-packages\keras\utils\traceback_utils.py", line 70, in error_handler
    raise e.with_traceback(filtered_tb) from None
  File "C:\Users\PCAdmin\.conda\envs\kidney\lib\site-packages\keras\saving\legacy\save.py", line 230, in load_model
    raise IOError(
OSError: No file or directory found at model\model.h5
[2025-03-16 19:14:22,302: INFO: _internal: 127.0.0.1 - - [16/Mar/2025 19:14:22] "[35m[1mPOST /predict HTTP/1.1[0m" 500 -]
[2025-03-16 19:17:17,448: INFO: _internal: [31m[1mWARNING: This is a development server. Do not use it in a production deployment. Use a production WSGI server instead.[0m
 * Running on all addresses (0.0.0.0)
 * Running on http://127.0.0.1:8080
 * Running on http://192.168.137.222:8080]
[2025-03-16 19:17:17,448: INFO: _internal: [33mPress CTRL+C to quit[0m]
[2025-03-16 19:17:21,171: INFO: _internal: 127.0.0.1 - - [16/Mar/2025 19:17:21] "GET / HTTP/1.1" 200 -]
[2025-03-16 19:17:32,791: INFO: _internal: 127.0.0.1 - - [16/Mar/2025 19:17:32] "POST /predict HTTP/1.1" 200 -]
[2025-03-16 19:24:37,724: INFO: _internal: 127.0.0.1 - - [16/Mar/2025 19:24:37] "POST /predict HTTP/1.1" 200 -]
