[2025-01-26 15:21:08,654: INFO: main: Welcome to our custom log]
[2025-01-26 15:24:00,322: INFO: main: Welcome to our custom log]
[2025-03-03 23:15:38,250: INFO: common: yaml file: config\config.yaml loaded successfully]
[2025-03-03 23:15:38,265: INFO: common: yaml file: params.yaml loaded successfully]
[2025-03-03 23:15:38,267: INFO: common: created directory at: artifacts]
[2025-03-03 23:15:38,271: INFO: common: created directory at: artifacts/data_ingestion]
[2025-03-03 23:15:38,272: INFO: 986331348: Downloading data from https://drive.google.com/file/d/1vlhZ5c7abUKF8xXERIw6m9Te8fW7ohw3/view?usp=sharing into file artifacts/data_ingestion/data.zip]
[2025-03-03 23:16:37,429: INFO: 986331348: Downloaded data from https://drive.google.com/file/d/1vlhZ5c7abUKF8xXERIw6m9Te8fW7ohw3/view?usp=sharing into file artifacts/data_ingestion/data.zip]
[2025-03-03 23:33:08,098: INFO: main: >>>>>> stage Data Ingestion stage started <<<<<<]
[2025-03-03 23:33:08,100: INFO: common: yaml file: config\config.yaml loaded successfully]
[2025-03-03 23:33:08,101: INFO: common: yaml file: params.yaml loaded successfully]
[2025-03-03 23:33:08,102: INFO: common: created directory at: artifacts]
[2025-03-03 23:33:08,103: INFO: common: created directory at: artifacts/data_ingestion]
[2025-03-03 23:33:08,103: INFO: data_ingestion: Downloading data from https://drive.google.com/file/d/1vlhZ5c7abUKF8xXERIw6m9Te8fW7ohw3/view?usp=sharing into file artifacts/data_ingestion/data.zip]
[2025-03-03 23:33:42,783: ERROR: main: ("Connection broken: ConnectionAbortedError(10053, 'An established connection was aborted by the software in your host machine', None, 10053, None)", ConnectionAbortedError(10053, 'An established connection was aborted by the software in your host machine', None, 10053, None))]
Traceback (most recent call last):
  File "C:\Users\PCAdmin\.conda\envs\kidney\lib\site-packages\urllib3\response.py", line 748, in _error_catcher
    yield
  File "C:\Users\PCAdmin\.conda\envs\kidney\lib\site-packages\urllib3\response.py", line 873, in _raw_read
    data = self._fp_read(amt, read1=read1) if not fp_closed else b""
  File "C:\Users\PCAdmin\.conda\envs\kidney\lib\site-packages\urllib3\response.py", line 856, in _fp_read
    return self._fp.read(amt) if amt is not None else self._fp.read()
  File "C:\Users\PCAdmin\.conda\envs\kidney\lib\http\client.py", line 459, in read
    n = self.readinto(b)
  File "C:\Users\PCAdmin\.conda\envs\kidney\lib\http\client.py", line 503, in readinto
    n = self.fp.readinto(b)
  File "C:\Users\PCAdmin\.conda\envs\kidney\lib\socket.py", line 681, in readinto
    return self._sock.recv_into(b)
  File "C:\Users\PCAdmin\.conda\envs\kidney\lib\ssl.py", line 1274, in recv_into
    return self.read(nbytes, buffer)
  File "C:\Users\PCAdmin\.conda\envs\kidney\lib\ssl.py", line 1132, in read
    return self._sslobj.read(len, buffer)
ConnectionAbortedError: [WinError 10053] An established connection was aborted by the software in your host machine

The above exception was the direct cause of the following exception:

Traceback (most recent call last):
  File "C:\Users\PCAdmin\.conda\envs\kidney\lib\site-packages\requests\models.py", line 820, in generate
    yield from self.raw.stream(chunk_size, decode_content=True)
  File "C:\Users\PCAdmin\.conda\envs\kidney\lib\site-packages\urllib3\response.py", line 1060, in stream
    data = self.read(amt=amt, decode_content=decode_content)
  File "C:\Users\PCAdmin\.conda\envs\kidney\lib\site-packages\urllib3\response.py", line 949, in read
    data = self._raw_read(amt)
  File "C:\Users\PCAdmin\.conda\envs\kidney\lib\site-packages\urllib3\response.py", line 902, in _raw_read
    self._fp.close()
  File "C:\Users\PCAdmin\.conda\envs\kidney\lib\contextlib.py", line 131, in __exit__
    self.gen.throw(type, value, traceback)
  File "C:\Users\PCAdmin\.conda\envs\kidney\lib\site-packages\urllib3\response.py", line 775, in _error_catcher
    raise ProtocolError(f"Connection broken: {e!r}", e) from e
urllib3.exceptions.ProtocolError: ("Connection broken: ConnectionAbortedError(10053, 'An established connection was aborted by the software in your host machine', None, 10053, None)", ConnectionAbortedError(10053, 'An established connection was aborted by the software in your host machine', None, 10053, None))

During handling of the above exception, another exception occurred:

Traceback (most recent call last):
  File "main.py", line 8, in <module>
    data_ingestion.main()
  File "c:\users\pcadmin\documents\keshtech\dsml\kidney-disease-classification-deep-learning-project\src\cnnClassifier\pipeline\stage_01_data_ingestion.py", line 15, in main
    data_ingestion.download_file()
  File "c:\users\pcadmin\documents\keshtech\dsml\kidney-disease-classification-deep-learning-project\src\cnnClassifier\components\data_ingestion.py", line 31, in download_file
    raise e
  File "c:\users\pcadmin\documents\keshtech\dsml\kidney-disease-classification-deep-learning-project\src\cnnClassifier\components\data_ingestion.py", line 26, in download_file
    gdown.download(prefix+file_id,zip_download_dir)
  File "C:\Users\PCAdmin\.conda\envs\kidney\lib\site-packages\gdown\download.py", line 368, in download
    for chunk in res.iter_content(chunk_size=CHUNK_SIZE):
  File "C:\Users\PCAdmin\.conda\envs\kidney\lib\site-packages\requests\models.py", line 822, in generate
    raise ChunkedEncodingError(e)
requests.exceptions.ChunkedEncodingError: ("Connection broken: ConnectionAbortedError(10053, 'An established connection was aborted by the software in your host machine', None, 10053, None)", ConnectionAbortedError(10053, 'An established connection was aborted by the software in your host machine', None, 10053, None))
[2025-03-03 23:34:26,791: INFO: main: >>>>>> stage Data Ingestion stage started <<<<<<]
[2025-03-03 23:34:26,792: INFO: common: yaml file: config\config.yaml loaded successfully]
[2025-03-03 23:34:26,793: INFO: common: yaml file: params.yaml loaded successfully]
[2025-03-03 23:34:26,793: INFO: common: created directory at: artifacts]
[2025-03-03 23:34:26,794: INFO: common: created directory at: artifacts/data_ingestion]
[2025-03-03 23:34:26,794: INFO: data_ingestion: Downloading data from https://drive.google.com/file/d/1vlhZ5c7abUKF8xXERIw6m9Te8fW7ohw3/view?usp=sharing into file artifacts/data_ingestion/data.zip]
[2025-03-03 23:34:53,246: ERROR: main: ("Connection broken: ConnectionAbortedError(10053, 'An established connection was aborted by the software in your host machine', None, 10053, None)", ConnectionAbortedError(10053, 'An established connection was aborted by the software in your host machine', None, 10053, None))]
Traceback (most recent call last):
  File "C:\Users\PCAdmin\.conda\envs\kidney\lib\site-packages\urllib3\response.py", line 748, in _error_catcher
    yield
  File "C:\Users\PCAdmin\.conda\envs\kidney\lib\site-packages\urllib3\response.py", line 873, in _raw_read
    data = self._fp_read(amt, read1=read1) if not fp_closed else b""
  File "C:\Users\PCAdmin\.conda\envs\kidney\lib\site-packages\urllib3\response.py", line 856, in _fp_read
    return self._fp.read(amt) if amt is not None else self._fp.read()
  File "C:\Users\PCAdmin\.conda\envs\kidney\lib\http\client.py", line 459, in read
    n = self.readinto(b)
  File "C:\Users\PCAdmin\.conda\envs\kidney\lib\http\client.py", line 503, in readinto
    n = self.fp.readinto(b)
  File "C:\Users\PCAdmin\.conda\envs\kidney\lib\socket.py", line 681, in readinto
    return self._sock.recv_into(b)
  File "C:\Users\PCAdmin\.conda\envs\kidney\lib\ssl.py", line 1274, in recv_into
    return self.read(nbytes, buffer)
  File "C:\Users\PCAdmin\.conda\envs\kidney\lib\ssl.py", line 1132, in read
    return self._sslobj.read(len, buffer)
ConnectionAbortedError: [WinError 10053] An established connection was aborted by the software in your host machine

The above exception was the direct cause of the following exception:

Traceback (most recent call last):
  File "C:\Users\PCAdmin\.conda\envs\kidney\lib\site-packages\requests\models.py", line 820, in generate
    yield from self.raw.stream(chunk_size, decode_content=True)
  File "C:\Users\PCAdmin\.conda\envs\kidney\lib\site-packages\urllib3\response.py", line 1060, in stream
    data = self.read(amt=amt, decode_content=decode_content)
  File "C:\Users\PCAdmin\.conda\envs\kidney\lib\site-packages\urllib3\response.py", line 949, in read
    data = self._raw_read(amt)
  File "C:\Users\PCAdmin\.conda\envs\kidney\lib\site-packages\urllib3\response.py", line 902, in _raw_read
    self._fp.close()
  File "C:\Users\PCAdmin\.conda\envs\kidney\lib\contextlib.py", line 131, in __exit__
    self.gen.throw(type, value, traceback)
  File "C:\Users\PCAdmin\.conda\envs\kidney\lib\site-packages\urllib3\response.py", line 775, in _error_catcher
    raise ProtocolError(f"Connection broken: {e!r}", e) from e
urllib3.exceptions.ProtocolError: ("Connection broken: ConnectionAbortedError(10053, 'An established connection was aborted by the software in your host machine', None, 10053, None)", ConnectionAbortedError(10053, 'An established connection was aborted by the software in your host machine', None, 10053, None))

During handling of the above exception, another exception occurred:

Traceback (most recent call last):
  File "main.py", line 8, in <module>
    data_ingestion.main()
  File "c:\users\pcadmin\documents\keshtech\dsml\kidney-disease-classification-deep-learning-project\src\cnnClassifier\pipeline\stage_01_data_ingestion.py", line 15, in main
    data_ingestion.download_file()
  File "c:\users\pcadmin\documents\keshtech\dsml\kidney-disease-classification-deep-learning-project\src\cnnClassifier\components\data_ingestion.py", line 31, in download_file
    raise e
  File "c:\users\pcadmin\documents\keshtech\dsml\kidney-disease-classification-deep-learning-project\src\cnnClassifier\components\data_ingestion.py", line 26, in download_file
    gdown.download(prefix+file_id,zip_download_dir)
  File "C:\Users\PCAdmin\.conda\envs\kidney\lib\site-packages\gdown\download.py", line 368, in download
    for chunk in res.iter_content(chunk_size=CHUNK_SIZE):
  File "C:\Users\PCAdmin\.conda\envs\kidney\lib\site-packages\requests\models.py", line 822, in generate
    raise ChunkedEncodingError(e)
requests.exceptions.ChunkedEncodingError: ("Connection broken: ConnectionAbortedError(10053, 'An established connection was aborted by the software in your host machine', None, 10053, None)", ConnectionAbortedError(10053, 'An established connection was aborted by the software in your host machine', None, 10053, None))
[2025-03-03 23:35:30,544: INFO: main: >>>>>> stage Data Ingestion stage started <<<<<<]
[2025-03-03 23:35:30,545: INFO: common: yaml file: config\config.yaml loaded successfully]
[2025-03-03 23:35:30,546: INFO: common: yaml file: params.yaml loaded successfully]
[2025-03-03 23:35:30,547: INFO: common: created directory at: artifacts]
[2025-03-03 23:35:30,547: INFO: common: created directory at: artifacts/data_ingestion]
[2025-03-03 23:35:30,549: INFO: data_ingestion: Downloading data from https://drive.google.com/file/d/1vlhZ5c7abUKF8xXERIw6m9Te8fW7ohw3/view?usp=sharing into file artifacts/data_ingestion/data.zip]
[2025-03-03 23:37:19,064: ERROR: main: ("Connection broken: ConnectionAbortedError(10053, 'An established connection was aborted by the software in your host machine', None, 10053, None)", ConnectionAbortedError(10053, 'An established connection was aborted by the software in your host machine', None, 10053, None))]
Traceback (most recent call last):
  File "C:\Users\PCAdmin\.conda\envs\kidney\lib\site-packages\urllib3\response.py", line 748, in _error_catcher
    yield
  File "C:\Users\PCAdmin\.conda\envs\kidney\lib\site-packages\urllib3\response.py", line 873, in _raw_read
    data = self._fp_read(amt, read1=read1) if not fp_closed else b""
  File "C:\Users\PCAdmin\.conda\envs\kidney\lib\site-packages\urllib3\response.py", line 856, in _fp_read
    return self._fp.read(amt) if amt is not None else self._fp.read()
  File "C:\Users\PCAdmin\.conda\envs\kidney\lib\http\client.py", line 459, in read
    n = self.readinto(b)
  File "C:\Users\PCAdmin\.conda\envs\kidney\lib\http\client.py", line 503, in readinto
    n = self.fp.readinto(b)
  File "C:\Users\PCAdmin\.conda\envs\kidney\lib\socket.py", line 681, in readinto
    return self._sock.recv_into(b)
  File "C:\Users\PCAdmin\.conda\envs\kidney\lib\ssl.py", line 1274, in recv_into
    return self.read(nbytes, buffer)
  File "C:\Users\PCAdmin\.conda\envs\kidney\lib\ssl.py", line 1132, in read
    return self._sslobj.read(len, buffer)
ConnectionAbortedError: [WinError 10053] An established connection was aborted by the software in your host machine

The above exception was the direct cause of the following exception:

Traceback (most recent call last):
  File "C:\Users\PCAdmin\.conda\envs\kidney\lib\site-packages\requests\models.py", line 820, in generate
    yield from self.raw.stream(chunk_size, decode_content=True)
  File "C:\Users\PCAdmin\.conda\envs\kidney\lib\site-packages\urllib3\response.py", line 1060, in stream
    data = self.read(amt=amt, decode_content=decode_content)
  File "C:\Users\PCAdmin\.conda\envs\kidney\lib\site-packages\urllib3\response.py", line 949, in read
    data = self._raw_read(amt)
  File "C:\Users\PCAdmin\.conda\envs\kidney\lib\site-packages\urllib3\response.py", line 902, in _raw_read
    self._fp.close()
  File "C:\Users\PCAdmin\.conda\envs\kidney\lib\contextlib.py", line 131, in __exit__
    self.gen.throw(type, value, traceback)
  File "C:\Users\PCAdmin\.conda\envs\kidney\lib\site-packages\urllib3\response.py", line 775, in _error_catcher
    raise ProtocolError(f"Connection broken: {e!r}", e) from e
urllib3.exceptions.ProtocolError: ("Connection broken: ConnectionAbortedError(10053, 'An established connection was aborted by the software in your host machine', None, 10053, None)", ConnectionAbortedError(10053, 'An established connection was aborted by the software in your host machine', None, 10053, None))

During handling of the above exception, another exception occurred:

Traceback (most recent call last):
  File "main.py", line 8, in <module>
    data_ingestion.main()
  File "c:\users\pcadmin\documents\keshtech\dsml\kidney-disease-classification-deep-learning-project\src\cnnClassifier\pipeline\stage_01_data_ingestion.py", line 15, in main
    data_ingestion.download_file()
  File "c:\users\pcadmin\documents\keshtech\dsml\kidney-disease-classification-deep-learning-project\src\cnnClassifier\components\data_ingestion.py", line 31, in download_file
    raise e
  File "c:\users\pcadmin\documents\keshtech\dsml\kidney-disease-classification-deep-learning-project\src\cnnClassifier\components\data_ingestion.py", line 26, in download_file
    gdown.download(prefix+file_id,zip_download_dir)
  File "C:\Users\PCAdmin\.conda\envs\kidney\lib\site-packages\gdown\download.py", line 368, in download
    for chunk in res.iter_content(chunk_size=CHUNK_SIZE):
  File "C:\Users\PCAdmin\.conda\envs\kidney\lib\site-packages\requests\models.py", line 822, in generate
    raise ChunkedEncodingError(e)
requests.exceptions.ChunkedEncodingError: ("Connection broken: ConnectionAbortedError(10053, 'An established connection was aborted by the software in your host machine', None, 10053, None)", ConnectionAbortedError(10053, 'An established connection was aborted by the software in your host machine', None, 10053, None))
[2025-03-03 23:38:19,149: INFO: main: >>>>>> stage Data Ingestion stage started <<<<<<]
[2025-03-03 23:38:19,150: INFO: common: yaml file: config\config.yaml loaded successfully]
[2025-03-03 23:38:19,152: INFO: common: yaml file: params.yaml loaded successfully]
[2025-03-03 23:38:19,152: INFO: common: created directory at: artifacts]
[2025-03-03 23:38:19,153: INFO: common: created directory at: artifacts/data_ingestion]
[2025-03-03 23:38:19,154: INFO: data_ingestion: Downloading data from https://drive.google.com/file/d/1vlhZ5c7abUKF8xXERIw6m9Te8fW7ohw3/view?usp=sharing into file artifacts/data_ingestion/data.zip]
[2025-03-03 23:38:53,769: ERROR: main: ("Connection broken: ConnectionAbortedError(10053, 'An established connection was aborted by the software in your host machine', None, 10053, None)", ConnectionAbortedError(10053, 'An established connection was aborted by the software in your host machine', None, 10053, None))]
Traceback (most recent call last):
  File "C:\Users\PCAdmin\.conda\envs\kidney\lib\site-packages\urllib3\response.py", line 748, in _error_catcher
    yield
  File "C:\Users\PCAdmin\.conda\envs\kidney\lib\site-packages\urllib3\response.py", line 873, in _raw_read
    data = self._fp_read(amt, read1=read1) if not fp_closed else b""
  File "C:\Users\PCAdmin\.conda\envs\kidney\lib\site-packages\urllib3\response.py", line 856, in _fp_read
    return self._fp.read(amt) if amt is not None else self._fp.read()
  File "C:\Users\PCAdmin\.conda\envs\kidney\lib\http\client.py", line 459, in read
    n = self.readinto(b)
  File "C:\Users\PCAdmin\.conda\envs\kidney\lib\http\client.py", line 503, in readinto
    n = self.fp.readinto(b)
  File "C:\Users\PCAdmin\.conda\envs\kidney\lib\socket.py", line 681, in readinto
    return self._sock.recv_into(b)
  File "C:\Users\PCAdmin\.conda\envs\kidney\lib\ssl.py", line 1274, in recv_into
    return self.read(nbytes, buffer)
  File "C:\Users\PCAdmin\.conda\envs\kidney\lib\ssl.py", line 1132, in read
    return self._sslobj.read(len, buffer)
ConnectionAbortedError: [WinError 10053] An established connection was aborted by the software in your host machine

The above exception was the direct cause of the following exception:

Traceback (most recent call last):
  File "C:\Users\PCAdmin\.conda\envs\kidney\lib\site-packages\requests\models.py", line 820, in generate
    yield from self.raw.stream(chunk_size, decode_content=True)
  File "C:\Users\PCAdmin\.conda\envs\kidney\lib\site-packages\urllib3\response.py", line 1060, in stream
    data = self.read(amt=amt, decode_content=decode_content)
  File "C:\Users\PCAdmin\.conda\envs\kidney\lib\site-packages\urllib3\response.py", line 949, in read
    data = self._raw_read(amt)
  File "C:\Users\PCAdmin\.conda\envs\kidney\lib\site-packages\urllib3\response.py", line 902, in _raw_read
    self._fp.close()
  File "C:\Users\PCAdmin\.conda\envs\kidney\lib\contextlib.py", line 131, in __exit__
    self.gen.throw(type, value, traceback)
  File "C:\Users\PCAdmin\.conda\envs\kidney\lib\site-packages\urllib3\response.py", line 775, in _error_catcher
    raise ProtocolError(f"Connection broken: {e!r}", e) from e
urllib3.exceptions.ProtocolError: ("Connection broken: ConnectionAbortedError(10053, 'An established connection was aborted by the software in your host machine', None, 10053, None)", ConnectionAbortedError(10053, 'An established connection was aborted by the software in your host machine', None, 10053, None))

During handling of the above exception, another exception occurred:

Traceback (most recent call last):
  File "main.py", line 8, in <module>
    data_ingestion.main()
  File "c:\users\pcadmin\documents\keshtech\dsml\kidney-disease-classification-deep-learning-project\src\cnnClassifier\pipeline\stage_01_data_ingestion.py", line 15, in main
    data_ingestion.download_file()
  File "c:\users\pcadmin\documents\keshtech\dsml\kidney-disease-classification-deep-learning-project\src\cnnClassifier\components\data_ingestion.py", line 31, in download_file
    raise e
  File "c:\users\pcadmin\documents\keshtech\dsml\kidney-disease-classification-deep-learning-project\src\cnnClassifier\components\data_ingestion.py", line 26, in download_file
    gdown.download(prefix+file_id,zip_download_dir)
  File "C:\Users\PCAdmin\.conda\envs\kidney\lib\site-packages\gdown\download.py", line 368, in download
    for chunk in res.iter_content(chunk_size=CHUNK_SIZE):
  File "C:\Users\PCAdmin\.conda\envs\kidney\lib\site-packages\requests\models.py", line 822, in generate
    raise ChunkedEncodingError(e)
requests.exceptions.ChunkedEncodingError: ("Connection broken: ConnectionAbortedError(10053, 'An established connection was aborted by the software in your host machine', None, 10053, None)", ConnectionAbortedError(10053, 'An established connection was aborted by the software in your host machine', None, 10053, None))
[2025-03-03 23:39:44,005: INFO: main: >>>>>> stage Data Ingestion stage started <<<<<<]
[2025-03-03 23:39:44,007: INFO: common: yaml file: config\config.yaml loaded successfully]
[2025-03-03 23:39:44,008: INFO: common: yaml file: params.yaml loaded successfully]
[2025-03-03 23:39:44,009: INFO: common: created directory at: artifacts]
[2025-03-03 23:39:44,009: INFO: common: created directory at: artifacts/data_ingestion]
[2025-03-03 23:39:44,010: INFO: data_ingestion: Downloading data from https://drive.google.com/file/d/1vlhZ5c7abUKF8xXERIw6m9Te8fW7ohw3/view?usp=sharing into file artifacts/data_ingestion/data.zip]
[2025-03-03 23:40:18,555: ERROR: main: ("Connection broken: ConnectionAbortedError(10053, 'An established connection was aborted by the software in your host machine', None, 10053, None)", ConnectionAbortedError(10053, 'An established connection was aborted by the software in your host machine', None, 10053, None))]
Traceback (most recent call last):
  File "C:\Users\PCAdmin\.conda\envs\kidney\lib\site-packages\urllib3\response.py", line 748, in _error_catcher
    yield
  File "C:\Users\PCAdmin\.conda\envs\kidney\lib\site-packages\urllib3\response.py", line 873, in _raw_read
    data = self._fp_read(amt, read1=read1) if not fp_closed else b""
  File "C:\Users\PCAdmin\.conda\envs\kidney\lib\site-packages\urllib3\response.py", line 856, in _fp_read
    return self._fp.read(amt) if amt is not None else self._fp.read()
  File "C:\Users\PCAdmin\.conda\envs\kidney\lib\http\client.py", line 459, in read
    n = self.readinto(b)
  File "C:\Users\PCAdmin\.conda\envs\kidney\lib\http\client.py", line 503, in readinto
    n = self.fp.readinto(b)
  File "C:\Users\PCAdmin\.conda\envs\kidney\lib\socket.py", line 681, in readinto
    return self._sock.recv_into(b)
  File "C:\Users\PCAdmin\.conda\envs\kidney\lib\ssl.py", line 1274, in recv_into
    return self.read(nbytes, buffer)
  File "C:\Users\PCAdmin\.conda\envs\kidney\lib\ssl.py", line 1132, in read
    return self._sslobj.read(len, buffer)
ConnectionAbortedError: [WinError 10053] An established connection was aborted by the software in your host machine

The above exception was the direct cause of the following exception:

Traceback (most recent call last):
  File "C:\Users\PCAdmin\.conda\envs\kidney\lib\site-packages\requests\models.py", line 820, in generate
    yield from self.raw.stream(chunk_size, decode_content=True)
  File "C:\Users\PCAdmin\.conda\envs\kidney\lib\site-packages\urllib3\response.py", line 1060, in stream
    data = self.read(amt=amt, decode_content=decode_content)
  File "C:\Users\PCAdmin\.conda\envs\kidney\lib\site-packages\urllib3\response.py", line 949, in read
    data = self._raw_read(amt)
  File "C:\Users\PCAdmin\.conda\envs\kidney\lib\site-packages\urllib3\response.py", line 902, in _raw_read
    self._fp.close()
  File "C:\Users\PCAdmin\.conda\envs\kidney\lib\contextlib.py", line 131, in __exit__
    self.gen.throw(type, value, traceback)
  File "C:\Users\PCAdmin\.conda\envs\kidney\lib\site-packages\urllib3\response.py", line 775, in _error_catcher
    raise ProtocolError(f"Connection broken: {e!r}", e) from e
urllib3.exceptions.ProtocolError: ("Connection broken: ConnectionAbortedError(10053, 'An established connection was aborted by the software in your host machine', None, 10053, None)", ConnectionAbortedError(10053, 'An established connection was aborted by the software in your host machine', None, 10053, None))

During handling of the above exception, another exception occurred:

Traceback (most recent call last):
  File "main.py", line 8, in <module>
    data_ingestion.main()
  File "c:\users\pcadmin\documents\keshtech\dsml\kidney-disease-classification-deep-learning-project\src\cnnClassifier\pipeline\stage_01_data_ingestion.py", line 15, in main
    data_ingestion.download_file()
  File "c:\users\pcadmin\documents\keshtech\dsml\kidney-disease-classification-deep-learning-project\src\cnnClassifier\components\data_ingestion.py", line 31, in download_file
    raise e
  File "c:\users\pcadmin\documents\keshtech\dsml\kidney-disease-classification-deep-learning-project\src\cnnClassifier\components\data_ingestion.py", line 26, in download_file
    gdown.download(prefix+file_id,zip_download_dir)
  File "C:\Users\PCAdmin\.conda\envs\kidney\lib\site-packages\gdown\download.py", line 368, in download
    for chunk in res.iter_content(chunk_size=CHUNK_SIZE):
  File "C:\Users\PCAdmin\.conda\envs\kidney\lib\site-packages\requests\models.py", line 822, in generate
    raise ChunkedEncodingError(e)
requests.exceptions.ChunkedEncodingError: ("Connection broken: ConnectionAbortedError(10053, 'An established connection was aborted by the software in your host machine', None, 10053, None)", ConnectionAbortedError(10053, 'An established connection was aborted by the software in your host machine', None, 10053, None))
[2025-03-03 23:42:07,457: INFO: main: >>>>>> stage Data Ingestion stage started <<<<<<]
[2025-03-03 23:42:07,458: INFO: common: yaml file: config\config.yaml loaded successfully]
[2025-03-03 23:42:07,458: INFO: common: yaml file: params.yaml loaded successfully]
[2025-03-03 23:42:07,459: INFO: common: created directory at: artifacts]
[2025-03-03 23:42:07,460: INFO: common: created directory at: artifacts/data_ingestion]
[2025-03-03 23:42:07,460: INFO: data_ingestion: Downloading data from https://drive.google.com/file/d/1vlhZ5c7abUKF8xXERIw6m9Te8fW7ohw3/view?usp=sharing into file artifacts/data_ingestion/data.zip]
[2025-03-03 23:42:22,678: INFO: data_ingestion: Downloaded data from https://drive.google.com/file/d/1vlhZ5c7abUKF8xXERIw6m9Te8fW7ohw3/view?usp=sharing into file artifacts/data_ingestion/data.zip]
[2025-03-03 23:42:24,570: INFO: main: >>>>>> stage Data Ingestion stage completed <<<<<<

x==========x]
